Workbook
Name Ag: 'Database 1'!$G$3:$G$139
Name AgDA: 'Database 1'!$DF$3:$DF$185
Name Agmt: 'Database 1'!$G$423:$G$436
Name AgST: 'Database 1'!$DC$3:$DC$30
Name AgWT: 'Database 1'!$CW$3:$CW$285
Name Angle_Ag: 'Database 1'!$G$3:$G$139
Name angles: 'Database 1'!$D$3:$D$139
Name DA: 'Database 1'!$D$465:$D$647
Name Daag: 'Database 1'!$G$465:$G$647
Name DAnew: 'Database 1'!$DE$3:$DE$185
Name Ix: 'Database 1'!$DX$4:$DX$70
Name Lag: 'Database 1'!$CT$3:$CT$139
Name lightest: '[1]Database 1'!$DS$3:$DS$69
Name Lnew: 'Database 1'!$CS$3:$CS$139
Name MT: 'Database 1'!$D$423:$D$436
Name MTag: 'Database 1'!$CZ$3:$CZ$16
Name MTnew: 'Database 1'!$CY$3:$CY$16
Name rxWT: 'Database 1'!$AR$140:$AR$422
Name ryWT: 'Database 1'!$AV$140:$AV$422
Name ST: 'Database 1'!$D$437:$D$464
Name Stag: 'Database 1'!$G$437:$G$464
Name STnew: 'Database 1'!$DB$3:$DB$30
Name Wlightest: 'Database 1'!$DT$4:$DT$70
Name WT: 'Database 1'!$D$140:$D$422
Name Wtag: 'Database 1'!$I$140:$I$422
Name WTnew: 'Database 1'!$CV$3:$CV$285
Name WZx: 'Database 1'!$DW$4:$DW$70

Sheet Database 1
B2: Type | C2: EDI STD Nomenclature | D2: AISC Manual Label | E2: Boolean Vaiable | F2: Wt. (lb/ft) | G2: Ag | I2: Shorter leg | Q2: Longer leg | X2: thickness | AB2: k | AD2: x̅ | AE2: y̅ | AG2: xp | AH2: yp | AR2: rx | AV2: ry | CL2: Steel Type | CM2: ASTM Designation | CO2: Fy | CP2: Fu | CS2: Angles | CT2: Ag | CV2: WT | CW2: Ag | CY2: MT | CZ2: Ag | DB2: ST | DC2: Ag | DE2: Double Angle | DF2: Ag | DH2: Wide Flange Basic Propeprties | DQ2: Tables for Bending, Shear, Deflection Design And Analysis
B3: L | C3: L12X12X1-3/8 | D3: L12X12X1-3/8 | E3: F | F3: 105 | G3: 31.1 | H3: =D3 -> L12X12X1-3/8 | I3: 12 | J3: – | K3: – | L3: – | M3: – | N3: – | O3: – | P3: – | Q3: 12 | R3: – | S3: – | T3: – | U3: – | V3: – | W3: – | X3: 1.38 | Y3: – | Z3: – | AA3: 2.09 | AB3: 2.0625 | AC3: – | AD3: 3.5 | AE3: 3.5 | AF3: – | AG3: 1.3 | AH3: 1.3 | AI3: – | AJ3: 8.7 | AK3: – | AL3: – | AM3: – | AN3: – | AO3: 413 | AP3: 88.1 | AQ3: 48.6 | AR3: 3.64 | AS3: 413 | AT3: 88.1 | AU3: 48.6 | AV3: 3.64 | AW3: 165 | AX3: 2.3 | AY3: 33.3 | AZ3: 19.9 | BA3: 211 | BB3: – | BC3: – | BD3: – | BE3: – | BF3: – | BG3: – | BH3: – | BI3: 6.51 | BJ3: 0.627 | BK3: 1 | BL3: 661 | BM3: 8 | BN3: 0 | BO3: 8 | BP3: 4.02 | BQ3: 4.95 | BR3: 4.02 | BS3: 82.6 | BT3: – | BU3: 82.6 | BV3: 41 | BW3: 33.3 | BX3: 41 | BY3: – | BZ3: – | CA3: 36 | CB3: 36 | CC3: 48 | CD3: – | CE3: – | CF3: – | CG3: – | CH3: – | CL3: Carbon | CM3: A36 | CN3: - | CO3: 36 | CP3: 58 | CS3: =VLOOKUP(CT3,$G$3:$H$139,2,FALSE) -> L12X12X1-3/8 | CT3: 31.1 | CV3: =VLOOKUP(CW3,$G$140:$H$422,2,FALSE) -> WT18X462.5 | CW3: 136 | CY3: =VLOOKUP(CZ3,$G$423:$H$436,2,FALSE) -> MT2.5X9.45 | CZ3: 2.78 | DB3: =VLOOKUP(DC3,$G$437:$H$464,2,FALSE) -> ST12X60.5 | DC3: 17.8 | DE3: =VLOOKUP(DF3,$G$465:$H$647,2,FALSE) -> 2L12X12X1-3/8 | DF3: 62.2 | DH3: Wide Flange | DI3: Ag | DJ3: d | DK3: tw | DL3: h/tw | DM3: bf/2tf | DN3: Zx | DO3: Sx | DQ3: Wide Flange | DR3: Zx | DS3: Ix | DT3: Lightest Sections | DU3: Ag | DV3: W | DW3: Zx | DX3: Ix | DZ3: TABLE 1-1 W-SHAPES DIMENSIONS | EW3: EFFECTIVE LENGTH FACTOR
B4: L | C4: L12X12X1-1/4 | D4: L12X12X1-1/4 | E4: F | F4: 96.4 | G4: 28.4 | H4: =D4 -> L12X12X1-1/4 | I4: 12 | J4: – | K4: – | L4: – | M4: – | N4: – | O4: – | P4: – | Q4: 12 | R4: – | S4: – | T4: – | U4: – | V4: – | W4: – | X4: 1.25 | Y4: – | Z4: – | AA4: 1.96 | AB4: 1.9375 | AC4: – | AD4: 3.45 | AE4: 3.45 | AF4: – | AG4: 1.18 | AH4: 1.18 | AI4: – | AJ4: 9.6 | AK4: – | AL4: – | AM4: – | AN4: – | AO4: 381 | AP4: 80.7 | AQ4: 44.6 | AR4: 3.66 | AS4: 381 | AT4: 80.7 | AU4: 44.6 | AV4: 3.66 | AW4: 152 | AX4: 2.31 | AY4: 31.1 | AZ4: 14.9 | BA4: 160 | BB4: – | BC4: – | BD4: – | BE4: – | BF4: – | BG4: – | BH4: – | BI4: 6.54 | BJ4: 0.627 | BK4: 1 | BL4: 610 | BM4: 8.04 | BN4: 0 | BO4: 8.04 | BP4: 4.05 | BQ4: 4.88 | BR4: 4.05 | BS4: 75.9 | BT4: – | BU4: 75.9 | BV4: 37.5 | BW4: 31.1 | BX4: 37.5 | BY4: – | BZ4: – | CA4: 36 | CB4: 36 | CC4: 48 | CD4: – | CE4: – | CF4: – | CG4: – | CH4: – | CM4: A53 Gr. B | CN4: Gr. B | CO4: 35 | CP4: 60 | CS4: =VLOOKUP(CT4,$G$3:$H$139,2,FALSE) -> L12X12X1-1/4 | CT4: 28.4 | CV4: =VLOOKUP(CW4,$G$140:$H$422,2,FALSE) -> WT7X436.5 | CW4: 129 | CY4: =VLOOKUP(CZ4,$G$423:$H$436,2,FALSE) -> MT6.25X6.2 | CZ4: 1.82 | DB4: =VLOOKUP(DC4,$G$437:$H$464,2,FALSE) -> ST12X53 | DC4: 15.6 | DE4: =VLOOKUP(DF4,$G$465:$H$647,2,FALSE) -> 2L12X12X1-3/8 | DF4: 62.2 | DH4: W44X335 | DI4: 98.5 | DJ4: 44 | DK4: 1.03 | DL4: 38 | DM4: 4.5 | DN4: 1620 | DO4: 1410 | DQ4: W36X925 | DR4: 4130 | DS4: 73000 | DT4: W36X925 | DU4: 4130 | DV4: 925 | DW4: =VLOOKUP(DT4,$DQ$4:$DR$276,2,FALSE) -> 4130 | DX4: =VLOOKUP(DT4,$DQ$4:$DS$276,3,FALSE) -> 73000
B5: L | C5: L12X12X1-1/8 | D5: L12X12X1-1/8 | E5: F | F5: 87.2 | G5: 25.8 | H5: =D5 -> L12X12X1-1/8 | I5: 12 | J5: – | K5: – | L5: – | M5: – | N5: – | O5: – | P5: – | Q5: 12 | R5: – | S5: – | T5: – | U5: – | V5: – | W5: – | X5: 1.13 | Y5: – | Z5: – | AA5: 1.84 | AB5: 1.8125 | AC5: – | AD5: 3.41 | AE5: 3.41 | AF5: – | AG5: 1.08 | AH5: 1.08 | AI5: – | AJ5: 10.6 | AK5: – | AL5: – | AM5: – | AN5: – | AO5: 350 | AP5: 73.7 | AQ5: 40.7 | AR5: 3.68 | AS5: 350 | AT5: 73.7 | AU5: 40.7 | AV5: 3.68 | AW5: 140 | AX5: 2.33 | AY5: 29 | AZ5: 11.1 | BA5: 120 | BB5: – | BC5: – | BD5: – | BE5: – | BF5: – | BG5: – | BH5: – | BI5: 6.58 | BJ5: 0.626 | BK5: 1 | BL5: 560 | BM5: 8.09 | BN5: 0 | BO5: 8.09 | BP5: 4.06 | BQ5: 4.82 | BR5: 4.06 | BS5: 69.2 | BT5: – | BU5: 69.2 | BV5: 34.5 | BW5: 29 | BX5: 34.5 | BY5: – | BZ5: – | CA5: 36 | CB5: 36 | CC5: 48 | CD5: – | CE5: – | CF5: – | CG5: – | CH5: – | CM5: A500 Gr. B-42 | CN5: Gr. B | CO5: 42 | CP5: 58 | CS5: =VLOOKUP(CT5,$G$3:$H$139,2,FALSE) -> L12X12X1-1/8 | CT5: 25.8 | CV5: =VLOOKUP(CW5,$G$140:$H$422,2,FALSE) -> WT18X426.5 | CW5: 126 | CY5: =VLOOKUP(CZ5,$G$423:$H$436,2,FALSE) -> MT6X5.9 | CZ5: 1.74 | DB5: =VLOOKUP(DC5,$G$437:$H$464,2,FALSE) -> ST12X50 | DC5: 14.7 | DE5: =VLOOKUP(DF5,$G$465:$H$647,2,FALSE) -> 2L12X12X1-3/8 | DF5: 62.2 | DH5: W44X290 | DI5: 85.4 | DJ5: 43.6 | DK5: 0.865 | DL5: 45 | DM5: 5.02 | DN5: 1410 | DO5: 1240 | DQ5: W36X853 | DR5: 3920 | DS5: 70000 | DT5: W36X853 | DU5: 3920 | DV5: 853 | DW5: =VLOOKUP(DT5,$DQ$4:$DR$276,2,FALSE) -> 3920 | DX5: =VLOOKUP(DT5,$DQ$4:$DS$276,3,FALSE) -> 70000
B6: L | C6: L12X12X1 | D6: L12X12X1 | E6: F | F6: 77.8 | G6: 23 | H6: =D6 -> L12X12X1 | I6: 12 | J6: – | K6: – | L6: – | M6: – | N6: – | O6: – | P6: – | Q6: 12 | R6: – | S6: – | T6: – | U6: – | V6: – | W6: – | X6: 1 | Y6: – | Z6: – | AA6: 1.71 | AB6: 1.6875 | AC6: – | AD6: 3.36 | AE6: 3.36 | AF6: – | AG6: 0.958 | AH6: 0.958 | AI6: – | AJ6: 12 | AK6: – | AL6: – | AM6: – | AN6: – | AO6: 315 | AP6: 65.9 | AQ6: 36.5 | AR6: 3.7 | AS6: 315 | AT6: ry+AT+AP2:AP138 | AU6: 36.5 | AV6: 3.7 | AW6: 126 | AX6: 2.34 | AY6: 26.5 | AZ6: 7.8 | BA6: 84.5 | BB6: – | BC6: – | BD6: – | BE6: – | BF6: – | BG6: – | BH6: – | BI6: 6.61 | BJ6: 0.626 | BK6: 1 | BL6: 504 | BM6: 8.13 | BN6: 0 | BO6: 8.13 | BP6: 4.09 | BQ6: 4.75 | BR6: 4.09 | BS6: 62 | BT6: – | BU6: 62 | BV6: 30.8 | BW6: 26.5 | BX6: 30.8 | BY6: – | BZ6: – | CA6: 36 | CB6: 36 | CC6: 48 | CD6: – | CE6: – | CF6: – | CG6: – | CH6: – | CM6: A500 Gr. B-46 | CN6: Gr. B | CO6: 46 | CP6: 58 | CS6: =VLOOKUP(CT6,$G$3:$H$139,2,FALSE) -> L10X10X1-3/8 | CT6: 25.6 | CV6: =VLOOKUP(CW6,$G$140:$H$422,2,FALSE) -> WT7X404 | CW6: 119 | CY6: =VLOOKUP(CZ6,$G$423:$H$436,2,FALSE) -> MT6.25X5.8 | CZ6: 1.7 | DB6: =VLOOKUP(DC6,$G$437:$H$464,2,FALSE) -> ST10X48 | DC6: 14.1 | DE6: =VLOOKUP(DF6,$G$465:$H$647,2,FALSE) -> 2L12X12X1-1/4 | DF6: 56.8 | DH6: W44X262 | DI6: 77.2 | DJ6: 43.3 | DK6: 0.785 | DL6: 49.6 | DM6: 5.57 | DN6: 1270 | DO6: 1110 | DQ6: W36X802 | DR6: 3660 | DS6: 64800 | DT6: W36X802 | DU6: 3660 | DV6: 802 | DW6: =VLOOKUP(DT6,$DQ$4:$DR$276,2,FALSE) -> 3660 | DX6: =VLOOKUP(DT6,$DQ$4:$DS$276,3,FALSE) -> 64800 | DZ6: Sections | EA6: W (lb/ft) | EB6: A (in.²) | EC6: d (in.) | ED6: ddet (in.) | EE6: tw (in.) | EF6: twdet (in.) | EG6: twdet/2 (in.) | EH6: bf (in.) | EI6: bfdet (in.) | EJ6: tf (in.) | EK6: tfdet (in.) | EL6: bf/2tf | EM6: h/tw | EN6: Ix (in.⁴) | EO6: Sx (in.³) | EP6: rx (in.) | EQ6: Zx (in.³) | ER6: Iy (in.⁴) | ES6: Sy (in.³) | ET6: ry (in.) | EU6: Zy (in.³) | EW6: Column End Conditions | EX6: k
B7: L | C7: L10X10X1-3/8 | D7: L10X10X1-3/8 | E7: F | F7: 87.1 | G7: 25.6 | H7: =D7 -> L10X10X1-3/8 | I7: 10 | J7: – | K7: – | L7: – | M7: – | N7: – | O7: – | P7: – | Q7: 10 | R7: – | S7: – | T7: – | U7: – | V7: – | W7: – | X7: 1.38 | Y7: – | Z7: – | AA7: 2.18 | AB7: 2.1875 | AC7: – | AD7: 3 | AE7: 3 | AF7: – | AG7: 1.28 | AH7: 1.28 | AI7: – | AJ7: 7.25 | AK7: – | AL7: – | AM7: – | AN7: – | AO7: 231 | AP7: 59.9 | AQ7: 33 | AR7: 3 | AS7: 231 | AT7: 59.8 | AU7: 33 | AV7: 3 | AW7: 93.3 | AX7: 1.91 | AY7: 22 | AZ7: 16.4 | BA7: 118 | BB7: – | BC7: – | BD7: – | BE7: – | BF7: – | BG7: – | BH7: – | BI7: 5.36 | BJ7: 0.629 | BK7: 1 | BL7: 369 | BM7: 6.58 | BN7: 0 | BO7: 6.58 | BP7: 3.32 | BQ7: 4.24 | BR7: 3.32 | BS7: 56.1 | BT7: – | BU7: 56.1 | BV7: 28.1 | BW7: 22 | BX7: 28.1 | BY7: – | BZ7: – | CA7: 30 | CB7: 30 | CC7: 40 | CD7: – | CE7: – | CF7: – | CG7: – | CH7: – | CM7: A500 Gr. C-46 | CN7: Gr. C | CO7: 46 | CP7: 62 | CS7: =VLOOKUP(CT7,$G$3:$H$139,2,FALSE) -> L10X10X1-1/4 | CT7: 23.4 | CV7: =VLOOKUP(CW7,$G$140:$H$422,2,FALSE) -> WT18X401 | CW7: 118 | CY7: =VLOOKUP(CZ7,$G$423:$H$436,2,FALSE) -> MT6X5.4 | CZ7: 1.59 | DB7: =VLOOKUP(DC7,$G$437:$H$464,2,FALSE) -> ST12X45 | DC7: 13.2 | DE7: =VLOOKUP(DF7,$G$465:$H$647,2,FALSE) -> 2L12X12X1-1/4 | DF7: 56.8 | DH7: W44X230 | DI7: 67.8 | DJ7: 42.9 | DK7: 0.71 | DL7: 54.8 | DM7: 6.45 | DN7: 1100 | DO7: 971 | DQ7: W36X723 | DR7: 3270 | DS7: 57300 | DT7: W36X723 | DU7: 3270 | DV7: 723 | DW7: =VLOOKUP(DT7,$DQ$4:$DR$276,2,FALSE) -> 3270 | DX7: =VLOOKUP(DT7,$DQ$4:$DS$276,3,FALSE) -> 57300 | EW7: Pinned-Pinned | EX7: 1
B8: L | C8: L10X10X1-1/4 | D8: L10X10X1-1/4 | E8: F | F8: 79.9 | G8: 23.4 | H8: =D8 -> L10X10X1-1/4 | I8: 10 | J8: – | K8: – | L8: – | M8: – | N8: – | O8: – | P8: – | Q8: 10 | R8: – | S8: – | T8: – | U8: – | V8: – | W8: – | X8: 1.25 | Y8: – | Z8: – | AA8: 2.05 | AB8: 2.0625 | AC8: – | AD8: 2.95 | AE8: 2.95 | AF8: – | AG8: 1.17 | AH8: 1.17 | AI8: – | AJ8: 8 | AK8: – | AL8: – | AM8: – | AN8: – | AO8: 213 | AP8: 54.9 | AQ8: 30.2 | AR8: 3.02 | AS8: 213 | AT8: 54.9 | AU8: 30.2 | AV8: 3.02 | AW8: 85.4 | AX8: 1.91 | AY8: 20.5 | AZ8: 12.3 | BA8: 89.4 | BB8: – | BC8: – | BD8: – | BE8: – | BF8: – | BG8: – | BH8: – | BI8: 5.39 | BJ8: 0.628 | BK8: 1 | BL8: 341 | BM8: 6.63 | BN8: 0 | BO8: 6.63 | BP8: 3.34 | BQ8: 4.17 | BR8: 3.34 | BS8: 51.4 | BT8: – | BU8: 51.4 | BV8: 25.6 | BW8: 20.5 | BX8: 25.6 | BY8: – | BZ8: – | CA8: 30 | CB8: 30 | CC8: 40 | CD8: – | CE8: – | CF8: – | CG8: – | CH8: – | CM8: A500 Gr. C-50 | CN8: Gr. C | CO8: 50 | CP8: 62 | CS8: =VLOOKUP(CT8,$G$3:$H$139,2,FALSE) -> L12X12X1 | CT8: 23 | CV8: =VLOOKUP(CW8,$G$140:$H$422,2,FALSE) -> WT18X361.5 | CW8: 107 | CY8: =VLOOKUP(CZ8,$G$423:$H$436,2,FALSE) -> MT6X5 | CZ8: 1.48 | DB8: =VLOOKUP(DC8,$G$437:$H$464,2,FALSE) -> ST10X43 | DC8: 12.7 | DE8: =VLOOKUP(DF8,$G$465:$H$647,2,FALSE) -> 2L12X12X1-1/4 | DF8: 56.8 | DH8: W40X655 | DI8: 193 | DJ8: 43.6 | DK8: 1.97 | DL8: 17.3 | DM8: 2.39 | DN8: 3080 | DO8: 2590 | DQ8: W40X655 | DR8: 3080 | DS8: 56500 | DT8: W40X655 | DU8: 3080 | DV8: 655 | DW8: =VLOOKUP(DT8,$DQ$4:$DR$276,2,FALSE) -> 3080 | DX8: =VLOOKUP(DT8,$DQ$4:$DS$276,3,FALSE) -> 56500 | DZ8: W44X335 | EA8: 335 | EB8: 98.5 | EC8: 44 | ED8: 44 | EE8: 1.03 | EF8: 1 | EG8: 44928 | EH8: 15.9 | EI8: 16 | EJ8: 1.77 | EK8: 1 3/4 | EL8: 4.5 | EM8: 38 | EN8: 31100 | EO8: 1410 | EP8: 17.8 | EQ8: 1620 | ER8: 1200 | ES8: 150 | ET8: 3.49 | EU8: 236 | EW8: Fixed-Fixed | EX8: 0.65
B9: L | C9: L10X10X1-1/8 | D9: L10X10X1-1/8 | E9: F | F9: 72.3 | G9: 21.3 | H9: =D9 -> L10X10X1-1/8 | I9: 10 | J9: – | K9: – | L9: – | M9: – | N9: – | O9: – | P9: – | Q9: 10 | R9: – | S9: – | T9: – | U9: – | V9: – | W9: – | X9: 1.13 | Y9: – | Z9: – | AA9: 1.93 | AB9: 1.9375 | AC9: – | AD9: 2.9 | AE9: 2.9 | AF9: – | AG9: 1.07 | AH9: 1.07 | AI9: – | AJ9: 8.85 | AK9: – | AL9: – | AM9: – | AN9: – | AO9: 196 | AP9: 50.2 | AQ9: 27.6 | AR9: 3.03 | AS9: 196 | AT9: 50.2 | AU9: 27.6 | AV9: 3.03 | AW9: 78.2 | AX9: 1.92 | AY9: 19.1 | AZ9: 9.21 | BA9: 67.3 | BB9: – | BC9: – | BD9: – | BE9: – | BF9: – | BG9: – | BH9: – | BI9: 5.41 | BJ9: 0.627 | BK9: 1 | BL9: 314 | BM9: 6.67 | BN9: 0 | BO9: 6.67 | BP9: 3.37 | BQ9: 4.1 | BR9: 3.37 | BS9: 47.1 | BT9: – | BU9: 47.1 | BV9: 23.2 | BW9: 19.1 | BX9: 23.2 | BY9: – | BZ9: – | CA9: 30 | CB9: 30 | CC9: 40 | CD9: – | CE9: – | CF9: – | CG9: – | CH9: – | CM9: A501 Gr. A-36 | CN9: Gr. A | CO9: 36 | CP9: 58 | CS9: =VLOOKUP(CT9,$G$3:$H$139,2,FALSE) -> L10X10X1-1/8 | CT9: 21.3 | CV9: =VLOOKUP(CW9,$G$140:$H$422,2,FALSE) -> WT18X361.5 | CW9: 107 | CY9: =VLOOKUP(CZ9,$G$423:$H$436,2,FALSE) -> MT5X4.5 | CZ9: 1.33 | DB9: =VLOOKUP(DC9,$G$437:$H$464,2,FALSE) -> ST12X40 | DC9: 11.7 | DE9: =VLOOKUP(DF9,$G$465:$H$647,2,FALSE) -> 2L12X12X1-1/8 | DF9: 51.6 | DH9: W40X593 | DI9: 174 | DJ9: 43 | DK9: 1.79 | DL9: 19.1 | DM9: 2.58 | DN9: 2760 | DO9: 2340 | DQ9: W36X652 | DR9: 2910 | DS9: 50600 | DT9: W36X652 | DU9: 2910 | DV9: 652 | DW9: =VLOOKUP(DT9,$DQ$4:$DR$276,2,FALSE) -> 2910 | DX9: =VLOOKUP(DT9,$DQ$4:$DS$276,3,FALSE) -> 50600 | DZ9: W44X290 | EA9: 290 | EB9: 85.4 | EC9: 43.6 | ED9: 43 5/8 | EE9: 0.865 | EF9: 45115 | EG9: 45123 | EH9: 15.8 | EI9: 15 7/8 | EJ9: 1.58 | EK9: 1 9/16 | EL9: 5.02 | EM9: 45 | EN9: 27000 | EO9: 1240 | EP9: 17.8 | EQ9: 1410 | ER9: 1040 | ES9: 132 | ET9: 3.49 | EU9: 205 | EW9: Fixed-Free | EX9: 2.1
B10: L | C10: L10X10X1 | D10: L10X10X1 | E10: F | F10: 64.7 | G10: 19 | H10: =D10 -> L10X10X1 | I10: 10 | J10: – | K10: – | L10: – | M10: – | N10: – | O10: – | P10: – | Q10: 10 | R10: – | S10: – | T10: – | U10: – | V10: – | W10: – | X10: 1 | Y10: – | Z10: – | AA10: 1.8 | AB10: 1.8125 | AC10: – | AD10: 2.86 | AE10: 2.86 | AF10: – | AG10: 0.95 | AH10: 0.95 | AI10: – | AJ10: 10 | AK10: – | AL10: – | AM10: – | AN10: – | AO10: 177 | AP10: 45 | AQ10: 24.8 | AR10: 3.05 | AS10: 177 | AT10: 45 | AU10: 24.8 | AV10: 3.05 | AW10: 70.4 | AX10: 1.92 | AY10: 17.4 | AZ10: 6.46 | BA10: 47.6 | BB10: – | BC10: – | BD10: – | BE10: – | BF10: – | BG10: – | BH10: – | BI10: 5.46 | BJ10: 0.626 | BK10: 1 | BL10: 284 | BM10: 6.72 | BN10: 0 | BO10: 6.72 | BP10: 3.38 | BQ10: 4.04 | BR10: 3.38 | BS10: 42.3 | BT10: – | BU10: 42.3 | BV10: 20.8 | BW10: 17.4 | BX10: 20.8 | BY10: – | BZ10: – | CA10: 30 | CB10: 30 | CC10: 40 | CD10: – | CE10: – | CF10: – | CG10: – | CH10: – | CM10: A501 Gr. B-50 | CN10: Gr. B | CO10: 50 | CP10: 70 | CS10: =VLOOKUP(CT10,$G$3:$H$139,2,FALSE) -> L10X10X1 | CT10: 19 | CV10: =VLOOKUP(CW10,$G$140:$H$422,2,FALSE) -> WT7X332.5 | CW10: 97.8 | CY10: =VLOOKUP(CZ10,$G$423:$H$436,2,FALSE) -> MT5X4 | CZ10: 1.19 | DB10: =VLOOKUP(DC10,$G$437:$H$464,2,FALSE) -> ST10X37.5 | DC10: 11 | DE10: =VLOOKUP(DF10,$G$465:$H$647,2,FALSE) -> 2L12X12X1-1/8 | DF10: 51.6 | DH10: W40X503 | DI10: 148 | DJ10: 42.1 | DK10: 1.54 | DL10: 22.3 | DM10: 2.98 | DN10: 2320 | DO10: 1980 | DQ10: W40X593 | DR10: 2760 | DS10: 50400 | DT10: W40X593 | DU10: 2760 | DV10: 593 | DW10: =VLOOKUP(DT10,$DQ$4:$DR$276,2,FALSE) -> 2760 | DX10: =VLOOKUP(DT10,$DQ$4:$DS$276,3,FALSE) -> 50400 | DZ10: W44X262 | EA10: 262 | EB10: 77.2 | EC10: 43.3 | ED10: 43 1/4 | EE10: 0.785 | EF10: 13/16 | EG10: 45123 | EH10: 15.8 | EI10: 15 3/4 | EJ10: 1.42 | EK10: 1 7/16 | EL10: 5.57 | EM10: 49.6 | EN10: 24100 | EO10: 1110 | EP10: 17.7 | EQ10: 1270 | ER10: 923 | ES10: 117 | ET10: 3.47 | EU10: 182 | EW10: Fixed-Pinned | EX10: 0.8
B11: L | C11: L10X10X7/8 | D11: L10X10X7/8 | E11: F | F11: 56.9 | G11: 16.8 | H11: =D11 -> L10X10X7/8 | I11: 10 | J11: – | K11: – | L11: – | M11: – | N11: – | O11: – | P11: – | Q11: 10 | R11: – | S11: – | T11: – | U11: – | V11: – | W11: – | X11: 0.875 | Y11: – | Z11: – | AA11: 1.68 | AB11: 1.6875 | AC11: – | AD11: 2.8 | AE11: 2.8 | AF11: – | AG11: 0.84 | AH11: 0.84 | AI11: – | AJ11: 11.4 | AK11: – | AL11: – | AM11: – | AN11: – | AO11: 158 | AP11: 39.9 | AQ11: 21.9 | AR11: 3.07 | AS11: 158 | AT11: 39.9 | AU11: 21.9 | AV11: 3.07 | AW11: 62.8 | AX11: 1.93 | AY11: 15.9 | AZ11: 4.39 | BA11: 32.5 | BB11: – | BC11: – | BD11: – | BE11: – | BF11: – | BG11: – | BH11: – | BI11: 5.47 | BJ11: 0.627 | BK11: 1 | BL11: 253 | BM11: 6.76 | BN11: 0 | BO11: 6.76 | BP11: 3.42 | BQ11: 3.96 | BR11: 3.42 | BS11: 37.4 | BT11: – | BU11: 37.4 | BV11: 18.4 | BW11: 15.9 | BX11: 18.4 | BY11: – | BZ11: – | CA11: 30 | CB11: 30 | CC11: 40 | CD11: – | CE11: – | CF11: – | CG11: – | CH11: – | CM11: A529 Gr. 50 | CN11: Grade 50 | CO11: 50 | CP11: 65 | CS11: =VLOOKUP(CT11,$G$3:$H$139,2,FALSE) -> L10X10X7/8 | CT11: 16.8 | CV11: =VLOOKUP(CW11,$G$140:$H$422,2,FALSE) -> WT20X327.5 | CW11: 96.4 | CY11: =VLOOKUP(CZ11,$G$423:$H$436,2,FALSE) -> MT5X3.75 | CZ11: 1.11 | DB11: =VLOOKUP(DC11,$G$437:$H$464,2,FALSE) -> ST9X35 | DC11: 10.3 | DE11: =VLOOKUP(DF11,$G$465:$H$647,2,FALSE) -> 2L12X12X1-1/8 | DF11: 51.6 | DH11: W40X431 | DI11: 127 | DJ11: 41.3 | DK11: 1.34 | DL11: 25.5 | DM11: 3.44 | DN11: 1960 | DO11: 1690 | DQ11: W36X529 | DR11: 2330 | DS11: 39600 | DT11: W36X529 | DU11: 2330 | DV11: 529 | DW11: =VLOOKUP(DT11,$DQ$4:$DR$276,2,FALSE) -> 2330 | DX11: =VLOOKUP(DT11,$DQ$4:$DS$276,3,FALSE) -> 39600 | DZ11: W44X230 | EA11: 230 | EB11: 67.8 | EC11: 42.9 | ED11: 42 7/8 | EE11: 0.71 | EF11: 45246 | EG11: 44993 | EH11: 15.8 | EI11: 15 3/4 | EJ11: 1.22 | EK11: 1 1/4 | EL11: 6.45 | EM11: 54.8 | EN11: 20800 | EO11: 971 | EP11: 17.5 | EQ11: 1100 | ER11: 796 | ES11: 101 | ET11: 3.43 | EU11: 157 | EW11: Fixed-Fixed but Translation Free | EX11: 1.2
B12: L | C12: L10X10X3/4 | D12: L10X10X3/4 | E12: F | F12: 49.1 | G12: 14.5 | H12: =D12 -> L10X10X3/4 | I12: 10 | J12: – | K12: – | L12: – | M12: – | N12: – | O12: – | P12: – | Q12: 10 | R12: – | S12: – | T12: – | U12: – | V12: – | W12: – | X12: 0.75 | Y12: – | Z12: – | AA12: 1.55 | AB12: 1.5625 | AC12: – | AD12: 2.76 | AE12: 2.76 | AF12: – | AG12: 0.725 | AH12: 0.725 | AI12: – | AJ12: 13.3 | AK12: – | AL12: – | AM12: – | AN12: – | AO12: 139 | AP12: 34.6 | AQ12: 19.2 | AR12: 3.1 | AS12: 139 | AT12: 34.6 | AU12: 19.2 | AV12: 3.1 | AW12: 55.7 | AX12: 1.96 | AY12: 14.3 | AZ12: 2.8 | BA12: 20.9 | BB12: – | BC12: – | BD12: – | BE12: – | BF12: – | BG12: – | BH12: – | BI12: 5.53 | BJ12: 0.628 | BK12: 1 | BL12: 222 | BM12: 6.81 | BN12: 0 | BO12: 6.81 | BP12: 3.43 | BQ12: 3.9 | BR12: 3.43 | BS12: 32.6 | BT12: – | BU12: 32.6 | BV12: 16.2 | BW12: 14.3 | BX12: 16.2 | BY12: – | BZ12: – | CA12: 30 | CB12: 30 | CC12: 40 | CD12: – | CE12: – | CF12: – | CG12: – | CH12: – | CM12: A529 Gr. 55 | CN12: Grade 55 | CO12: 55 | CP12: 70 | CS12: =VLOOKUP(CT12,$G$3:$H$139,2,FALSE) -> L10X10X7/8 | CT12: 16.8 | CV12: =VLOOKUP(CW12,$G$140:$H$422,2,FALSE) -> WT18X326 | CW12: 96.2 | CY12: =VLOOKUP(CZ12,$G$423:$H$436,2,FALSE) -> MT4X3.25 | CZ12: 0.959 | DB12: =VLOOKUP(DC12,$G$437:$H$464,2,FALSE) -> ST10X33 | DC12: 9.7 | DE12: =VLOOKUP(DF12,$G$465:$H$647,2,FALSE) -> 2L10X10X1-3/8 | DF12: 51.2 | DH12: W40X397 | DI12: 117 | DJ12: 41 | DK12: 1.22 | DL12: 28 | DM12: 3.66 | DN12: 1800 | DO12: 1560 | DQ12: W40X503 | DR12: 2320 | DS12: 41600 | DT12: W40X503 | DU12: 2320 | DV12: 503 | DW12: =VLOOKUP(DT12,$DQ$4:$DR$276,2,FALSE) -> 2320 | DX12: =VLOOKUP(DT12,$DQ$4:$DS$276,3,FALSE) -> 41600 | DZ12: W40X655 | EA12: 655 | EB12: 193 | EC12: 43.6 | ED12: 43 5/8 | EE12: 1.97 | EF12: 2 | EG12: 1 | EH12: 16.9 | EI12: 16 7/8 | EJ12: 3.54 | EK12: 3 9/16 | EL12: 2.39 | EM12: 17.3 | EN12: 56500 | EO12: 2590 | EP12: 17.1 | EQ12: 3080 | ER12: 2870 | ES12: 340 | ET12: 3.86 | EU12: 542 | EW12: Pinned-Fixed but Translation Free | EX12: 2
B13: L | C13: L8X8X1-1/8 | D13: L8X8X1-1/8 | E13: F | F13: 56.9 | G13: 16.8 | H13: =D13 -> L8X8X1-1/8 | I13: 8 | J13: – | K13: – | L13: – | M13: – | N13: – | O13: – | P13: – | Q13: 8 | R13: – | S13: – | T13: – | U13: – | V13: – | W13: – | X13: 1.13 | Y13: – | Z13: – | AA13: 1.75 | AB13: 1.75 | AC13: – | AD13: 2.4 | AE13: 2.4 | AF13: – | AG13: 1.05 | AH13: 1.05 | AI13: – | AJ13: 7.08 | AK13: – | AL13: – | AM13: – | AN13: – | AO13: 98.1 | AP13: 31.6 | AQ13: 17.5 | AR13: 2.41 | AS13: 98.1 | AT13: 31.6 | AU13: 17.5 | AV13: 2.41 | AW13: 40.7 | AX13: 1.56 | AY13: 12 | AZ13: 7.13 | BA13: 32.5 | BB13: – | BC13: – | BD13: – | BE13: – | BF13: – | BG13: – | BH13: – | BI13: 4.29 | BJ13: 0.63 | BK13: 1 | BL13: 155 | BM13: 5.26 | BN13: 0 | BO13: 5.26 | BP13: 2.66 | BQ13: 3.39 | BR13: 2.66 | BS13: 29.5 | BT13: – | BU13: 29.5 | BV13: 15.3 | BW13: 12 | BX13: 15.3 | BY13: – | BZ13: – | CA13: 24 | CB13: 24 | CC13: 32 | CD13: – | CE13: – | CF13: – | CG13: – | CH13: – | CM13: A709 | CN13: - | CO13: 36 | CP13: 58 | CS13: =VLOOKUP(CT13,$G$3:$H$139,2,FALSE) -> L8X8X1 | CT13: 15.1 | CV13: =VLOOKUP(CW13,$G$140:$H$422,2,FALSE) -> WT7X302.5 | CW13: 89 | CY13: =VLOOKUP(CZ13,$G$423:$H$436,2,FALSE) -> MT4X3.1 | CZ13: 0.911 | DB13: =VLOOKUP(DC13,$G$437:$H$464,2,FALSE) -> ST9X27.35 | DC13: 8.02 | DE13: =VLOOKUP(DF13,$G$465:$H$647,2,FALSE) -> 2L10X10X1-3/8 | DF13: 51.2 | DH13: W40X372 | DI13: 110 | DJ13: 40.6 | DK13: 1.16 | DL13: 29.5 | DM13: 3.93 | DN13: 1680 | DO13: 1460 | DQ13: W36X487 | DR13: 2130 | DS13: 36000 | DT13: W36X487 | DU13: 2130 | DV13: 487 | DW13: =VLOOKUP(DT13,$DQ$4:$DR$276,2,FALSE) -> 2130 | DX13: =VLOOKUP(DT13,$DQ$4:$DS$276,3,FALSE) -> 36000 | DZ13: W40X593 | EA13: 593 | EB13: 174 | EC13: 43 | ED13: 43 | EE13: 1.79 | EF13: 1 13/16 | EG13: 15/16 | EH13: 16.7 | EI13: 16 3/4 | EJ13: 3.23 | EK13: 3 1/4 | EL13: 2.58 | EM13: 19.1 | EN13: 50400 | EO13: 2340 | EP13: 17 | EQ13: 2760 | ER13: 2520 | ES13: 302 | ET13: 3.8 | EU13: 481 | EW13: N/A | EX13: 0
B14: L | C14: L8X8X1 | D14: L8X8X1 | E14: F | F14: 51 | G14: 15.1 | H14: =D14 -> L8X8X1 | I14: 8 | J14: – | K14: – | L14: – | M14: – | N14: – | O14: – | P14: – | Q14: 8 | R14: – | S14: – | T14: – | U14: – | V14: – | W14: – | X14: 1 | Y14: – | Z14: – | AA14: 1.63 | AB14: 1.625 | AC14: – | AD14: 2.36 | AE14: 2.36 | AF14: – | AG14: 0.944 | AH14: 0.944 | AI14: – | AJ14: 8 | AK14: – | AL14: – | AM14: – | AN14: – | AO14: 89.1 | AP14: 28.5 | AQ14: 15.8 | AR14: 2.43 | AS14: 89.1 | AT14: 28.5 | AU14: 15.8 | AV14: 2.43 | AW14: 36.8 | AX14: 1.56 | AY14: 11 | AZ14: 5.08 | BA14: 23.4 | BB14: – | BC14: – | BD14: – | BE14: – | BF14: – | BG14: – | BH14: – | BI14: 4.32 | BJ14: 0.63 | BK14: 1 | BL14: 141 | BM14: 5.3 | BN14: 0 | BO14: 5.3 | BP14: 2.67 | BQ14: 3.34 | BR14: 2.67 | BS14: 26.6 | BT14: – | BU14: 26.6 | BV14: 13.8 | BW14: 11 | BX14: 13.8 | BY14: – | BZ14: – | CA14: 24 | CB14: 24 | CC14: 32 | CD14: – | CE14: – | CF14: – | CG14: – | CH14: – | CM14: A1043 Gr. 36 | CN14: 36 | CO14: 36 | CP14: 58 | CS14: =VLOOKUP(CT14,$G$3:$H$139,2,FALSE) -> L10X10X3/4 | CT14: 14.5 | CV14: =VLOOKUP(CW14,$G$140:$H$422,2,FALSE) -> WT20X296.5 | CW14: 87.2 | CY14: =VLOOKUP(CZ14,$G$423:$H$436,2,FALSE) -> MT2X3 | CZ14: 0.875 | DB14: =VLOOKUP(DC14,$G$437:$H$464,2,FALSE) -> ST7.5X25 | DC14: 7.34 | DE14: =VLOOKUP(DF14,$G$465:$H$647,2,FALSE) -> 2L10X10X1-3/8 | DF14: 51.2 | DH14: W40X362 | DI14: 106 | DJ14: 40.6 | DK14: 1.12 | DL14: 30.5 | DM14: 3.99 | DN14: 1640 | DO14: 1420 | DQ14: W14X873 | DR14: 2030 | DS14: 18100 | DT14: W40X431 | DU14: 1960 | DV14: 431 | DW14: =VLOOKUP(DT14,$DQ$4:$DR$276,2,FALSE) -> 1960 | DX14: =VLOOKUP(DT14,$DQ$4:$DS$276,3,FALSE) -> 34800 | DZ14: W40X503 | EA14: 503 | EB14: 148 | EC14: 42.1 | ED14: 42 | EE14: 1.54 | EF14: 1 9/16 | EG14: 13/16 | EH14: 16.4 | EI14: 16 3/8 | EJ14: 2.76 | EK14: 2 3/4 | EL14: 2.98 | EM14: 22.3 | EN14: 41600 | EO14: 1980 | EP14: 16.8 | EQ14: 2320 | ER14: 2040 | ES14: 249 | ET14: 3.72 | EU14: 394
B15: L | C15: L8X8X7/8 | D15: L8X8X7/8 | E15: F | F15: 45 | G15: 13.3 | H15: =D15 -> L8X8X7/8 | I15: 8 | J15: – | K15: – | L15: – | M15: – | N15: – | O15: – | P15: – | Q15: 8 | R15: – | S15: – | T15: – | U15: – | V15: – | W15: – | X15: 0.875 | Y15: – | Z15: – | AA15: 1.5 | AB15: 1.5 | AC15: – | AD15: 2.31 | AE15: 2.31 | AF15: – | AG15: 0.831 | AH15: 0.831 | AI15: – | AJ15: 9.14 | AK15: – | AL15: – | AM15: – | AN15: – | AO15: 79.7 | AP15: 25.3 | AQ15: 14 | AR15: 2.45 | AS15: 79.7 | AT15: 25.3 | AU15: 14 | AV15: 2.45 | AW15: 32.7 | AX15: 1.57 | AY15: 10 | AZ15: 3.46 | BA15: 16.1 | BB15: – | BC15: – | BD15: – | BE15: – | BF15: – | BG15: – | BH15: – | BI15: 4.36 | BJ15: 0.63 | BK15: 1 | BL15: 127 | BM15: 5.35 | BN15: 0 | BO15: 5.35 | BP15: 2.7 | BQ15: 3.27 | BR15: 2.7 | BS15: 23.7 | BT15: – | BU15: 23.7 | BV15: 12.1 | BW15: 10 | BX15: 12.1 | BY15: – | BZ15: – | CA15: 24 | CB15: 24 | CC15: 32 | CD15: – | CE15: – | CF15: – | CG15: – | CH15: – | CM15: A1043 Gr. 50 | CN15: 50 | CO15: 50 | CP15: 65 | CS15: =VLOOKUP(CT15,$G$3:$H$139,2,FALSE) -> L8X8X7/8 | CT15: 13.3 | CV15: =VLOOKUP(CW15,$G$140:$H$422,2,FALSE) -> WT7X275 | CW15: 80.9 | CY15: =VLOOKUP(CZ15,$G$423:$H$436,2,FALSE) -> MT3X2.2 | CZ15: 0.647 | DB15: =VLOOKUP(DC15,$G$437:$H$464,2,FALSE) -> ST6X25 | DC15: 7.33 | DE15: =VLOOKUP(DF15,$G$465:$H$647,2,FALSE) -> 2L10X10X1-1/4 | DF15: 46.8 | DH15: W40X324 | DI15: 95.3 | DJ15: 40.2 | DK15: 1 | DL15: 34.2 | DM15: 4.4 | DN15: 1460 | DO15: 1280 | DQ15: W40X431 | DR15: 1960 | DS15: 34800 | DT15: W40X397 | DU15: 1800 | DV15: 397 | DW15: =VLOOKUP(DT15,$DQ$4:$DR$276,2,FALSE) -> 1800 | DX15: =VLOOKUP(DT15,$DQ$4:$DS$276,3,FALSE) -> 32000 | DZ15: W40X431 | EA15: 431 | EB15: 127 | EC15: 41.3 | ED15: 41 1/4 | EE15: 1.34 | EF15: 1 5/16 | EG15: 45246 | EH15: 16.2 | EI15: 16 1/4 | EJ15: 2.36 | EK15: 2 3/8 | EL15: 3.44 | EM15: 25.5 | EN15: 34800 | EO15: 1690 | EP15: 16.6 | EQ15: 1960 | ER15: 1690 | ES15: 208 | ET15: 3.65 | EU15: 328
B16: L | C16: L8X8X3/4 | D16: L8X8X3/4 | E16: F | F16: 38.9 | G16: 11.5 | H16: =D16 -> L8X8X3/4 | I16: 8 | J16: – | K16: – | L16: – | M16: – | N16: – | O16: – | P16: – | Q16: 8 | R16: – | S16: – | T16: – | U16: – | V16: – | W16: – | X16: 0.75 | Y16: – | Z16: – | AA16: 1.38 | AB16: 1.375 | AC16: – | AD16: 2.26 | AE16: 2.26 | AF16: – | AG16: 0.719 | AH16: 0.719 | AI16: – | AJ16: 10.7 | AK16: – | AL16: – | AM16: – | AN16: – | AO16: 69.9 | AP16: 22 | AQ16: 12.2 | AR16: 2.46 | AS16: 69.9 | AT16: 22 | AU16: 12.2 | AV16: 2.46 | AW16: 28.5 | AX16: 1.57 | AY16: 8.91 | AZ16: 2.21 | BA16: 10.4 | BB16: – | BC16: – | BD16: – | BE16: – | BF16: – | BG16: – | BH16: – | BI16: 4.39 | BJ16: 0.63 | BK16: 1 | BL16: 111 | BM16: 5.39 | BN16: 0 | BO16: 5.39 | BP16: 2.73 | BQ16: 3.2 | BR16: 2.73 | BS16: 20.6 | BT16: – | BU16: 20.6 | BV16: 10.4 | BW16: 8.91 | BX16: 10.4 | BY16: – | BZ16: – | CA16: 24 | CB16: 24 | CC16: 32 | CD16: – | CE16: – | CF16: – | CG16: – | CH16: – | CM16: A1085 | CN16: Gr. A | CO16: 50 | CP16: 65 | CS16: =VLOOKUP(CT16,$G$3:$H$139,2,FALSE) -> L8X6X1 | CT16: 13.1 | CV16: =VLOOKUP(CW16,$G$140:$H$422,2,FALSE) -> WT13.5X269.5 | CW16: 79.3 | CY16: =VLOOKUP(CZ16,$G$423:$H$436,2,FALSE) -> MT3X1.85 | CZ16: 0.545 | DB16: =VLOOKUP(DC16,$G$437:$H$464,2,FALSE) -> ST7.5X21.45 | DC16: 6.3 | DE16: =VLOOKUP(DF16,$G$465:$H$647,2,FALSE) -> 2L10X10X1-1/4 | DF16: 46.8 | DH16: W40X297 | DI16: 87.3 | DJ16: 39.8 | DK16: 0.93 | DL16: 36.8 | DM16: 4.8 | DN16: 1330 | DO16: 1170 | DQ16: W36X441 | DR16: 1910 | DS16: 32100 | DT16: W40X392 | DU16: 1710 | DV16: 392 | DW16: =VLOOKUP(DT16,$DQ$4:$DR$276,2,FALSE) -> 1710 | DX16: =VLOOKUP(DT16,$DQ$4:$DS$276,3,FALSE) -> 29900 | DZ16: W40X397 | EA16: 397 | EB16: 117 | EC16: 41 | ED16: 41 | EE16: 1.22 | EF16: 1 1/4 | EG16: 45054 | EH16: 16.1 | EI16: 16 1/8 | EJ16: 2.2 | EK16: 2 3/16 | EL16: 3.66 | EM16: 28 | EN16: 32000 | EO16: 1560 | EP16: 16.6 | EQ16: 1800 | ER16: 1540 | ES16: 191 | ET16: 3.64 | EU16: 300
B17: L | C17: L8X8X5/8 | D17: L8X8X5/8 | E17: F | F17: 32.7 | G17: 9.69 | H17: =D17 -> L8X8X5/8 | I17: 8 | J17: – | K17: – | L17: – | M17: – | N17: – | O17: – | P17: – | Q17: 8 | R17: – | S17: – | T17: – | U17: – | V17: – | W17: – | X17: 0.625 | Y17: – | Z17: – | AA17: 1.25 | AB17: 1.25 | AC17: – | AD17: 2.21 | AE17: 2.21 | AF17: – | AG17: 0.606 | AH17: 0.606 | AI17: – | AJ17: 12.8 | AK17: – | AL17: – | AM17: – | AN17: – | AO17: 59.6 | AP17: 18.6 | AQ17: 10.3 | AR17: 2.48 | AS17: 59.6 | AT17: 18.6 | AU17: 10.3 | AV17: 2.48 | AW17: 24.2 | AX17: 1.58 | AY17: 7.73 | AZ17: 1.3 | BA17: 6.16 | BB17: – | BC17: – | BD17: – | BE17: – | BF17: – | BG17: – | BH17: – | BI17: 4.42 | BJ17: 0.63 | BK17: 1 | BL17: 95 | BM17: 5.44 | BN17: 0 | BO17: 5.44 | BP17: 2.75 | BQ17: 3.13 | BR17: 2.75 | BS17: 17.5 | BT17: – | BU17: 17.5 | BV17: 8.8 | BW17: 7.73 | BX17: 8.8 | BY17: – | BZ17: – | CA17: 24 | CB17: 24 | CC17: 32 | CD17: – | CE17: – | CF17: – | CG17: – | CH17: – | CL17: Corrosion Resistant High-Strength Low-Alloy | CM17: A572 Gr. 42 | CN17: Grade 42 | CO17: 42 | CP17: 60 | CS17: =VLOOKUP(CT17,$G$3:$H$139,2,FALSE) -> L8X8X3/4 | CT17: 11.5 | CV17: =VLOOKUP(CW17,$G$140:$H$422,2,FALSE) -> WT18X264.5 | CW17: 77.8 | DB17: =VLOOKUP(DC17,$G$437:$H$464,2,FALSE) -> ST6X20.4 | DC17: 5.96 | DE17: =VLOOKUP(DF17,$G$465:$H$647,2,FALSE) -> 2L10X10X1-1/4 | DF17: 46.8 | DH17: W40X277 | DI17: 81.5 | DJ17: 39.7 | DK17: 0.83 | DL17: 41.2 | DM17: 5.03 | DN17: 1250 | DO17: 1100 | DQ17: W27X539 | DR17: 1890 | DS17: 25600 | DT17: W40X372 | DU17: 1680 | DV17: 372 | DW17: =VLOOKUP(DT17,$DQ$4:$DR$276,2,FALSE) -> 1680 | DX17: =VLOOKUP(DT17,$DQ$4:$DS$276,3,FALSE) -> 29600 | DZ17: W40X372 | EA17: 372 | EB17: 110 | EC17: 40.6 | ED17: 40 5/8 | EE17: 1.16 | EF17: 1 3/16 | EG17: 45054 | EH17: 16.1 | EI17: 16 1/8 | EJ17: 2.05 | EK17: 2 1/16 | EL17: 3.93 | EM17: 29.5 | EN17: 29600 | EO17: 1460 | EP17: 16.5 | EQ17: 1680 | ER17: 1420 | ES17: 177 | ET17: 3.6 | EU17: 277
B18: L | C18: L8X8X9/16 | D18: L8X8X9/16 | E18: F | F18: 29.6 | G18: 8.77 | H18: =D18 -> L8X8X9/16 | I18: 8 | J18: – | K18: – | L18: – | M18: – | N18: – | O18: – | P18: – | Q18: 8 | R18: – | S18: – | T18: – | U18: – | V18: – | W18: – | X18: 0.563 | Y18: – | Z18: – | AA18: 1.19 | AB18: 1.1875 | AC18: – | AD18: 2.19 | AE18: 2.19 | AF18: – | AG18: 0.548 | AH18: 0.548 | AI18: – | AJ18: 14.2 | AK18: – | AL18: – | AM18: – | AN18: – | AO18: 54.2 | AP18: 16.8 | AQ18: 9.33 | AR18: 2.49 | AS18: 54.2 | AT18: 16.8 | AU18: 9.33 | AV18: 2.49 | AW18: 21.9 | AX18: 1.58 | AY18: 7.06 | AZ18: 0.961 | BA18: 4.55 | BB18: – | BC18: – | BD18: – | BE18: – | BF18: – | BG18: – | BH18: – | BI18: 4.43 | BJ18: 0.63 | BK18: 1 | BL18: 86.4 | BM18: 5.46 | BN18: 0 | BO18: 5.46 | BP18: 2.76 | BQ18: 3.1 | BR18: 2.76 | BS18: 15.8 | BT18: – | BU18: 15.8 | BV18: 7.93 | BW18: 7.06 | BX18: 7.93 | BY18: – | BZ18: – | CA18: 24 | CB18: 24 | CC18: 32 | CD18: – | CE18: – | CF18: – | CG18: – | CH18: – | CM18: A572 Gr. 50 | CN18: Grade 50 | CO18: 50 | CP18: 65 | CS18: =VLOOKUP(CT18,$G$3:$H$139,2,FALSE) -> L8X8X3/4 | CT18: 11.5 | CV18: =VLOOKUP(CW18,$G$140:$H$422,2,FALSE) -> WT20X251.5 | CW18: 74 | DB18: =VLOOKUP(DC18,$G$437:$H$464,2,FALSE) -> ST5X17.5 | DC18: 5.14 | DE18: =VLOOKUP(DF18,$G$465:$H$647,2,FALSE) -> 2L12X12X1 | DF18: 46 | DH18: W40X249 | DI18: 73.5 | DJ18: 39.4 | DK18: 0.75 | DL18: 45.6 | DM18: 5.55 | DN18: 1120 | DO18: 993 | DQ18: W14X808 | DR18: 1830 | DS18: 15900 | DT18: W40X362 | DU18: 1640 | DV18: 362 | DW18: =VLOOKUP(DT18,$DQ$4:$DR$276,2,FALSE) -> 1640 | DX18: =VLOOKUP(DT18,$DQ$4:$DS$276,3,FALSE) -> 28900 | DZ18: W40X362 | EA18: 362 | EB18: 106 | EC18: 40.6 | ED18: 40 1/2 | EE18: 1.12 | EF18: 1 1/8 | EG18: 45185 | EH18: 16 | EI18: 16 | EJ18: 2.01 | EK18: 2 | EL18: 3.99 | EM18: 30.5 | EN18: 28900 | EO18: 1420 | EP18: 16.5 | EQ18: 1640 | ER18: 1380 | ES18: 173 | ET18: 3.6 | EU18: 270
B19: L | C19: L8X8X1/2 | D19: L8X8X1/2 | E19: F | F19: 26.4 | G19: 7.84 | H19: =D19 -> L8X8X1/2 | I19: 8 | J19: – | K19: – | L19: – | M19: – | N19: – | O19: – | P19: – | Q19: 8 | R19: – | S19: – | T19: – | U19: – | V19: – | W19: – | X19: 0.5 | Y19: – | Z19: – | AA19: 1.13 | AB19: 1.125 | AC19: – | AD19: 2.17 | AE19: 2.17 | AF19: – | AG19: 0.49 | AH19: 0.49 | AI19: – | AJ19: 16 | AK19: – | AL19: – | AM19: – | AN19: – | AO19: 48.8 | AP19: 15.1 | AQ19: 8.36 | AR19: 2.49 | AS19: 48.8 | AT19: 15.1 | AU19: 8.36 | AV19: 2.49 | AW19: 19.8 | AX19: 1.59 | AY19: 6.45 | AZ19: 0.683 | BA19: 3.23 | BB19: – | BC19: – | BD19: – | BE19: – | BF19: – | BG19: – | BH19: – | BI19: 4.45 | BJ19: 0.63 | BK19: 1 | BL19: 77.9 | BM19: 5.48 | BN19: 0 | BO19: 5.48 | BP19: 2.76 | BQ19: 3.07 | BR19: 2.76 | BS19: 14.2 | BT19: – | BU19: 14.2 | BV19: 7.17 | BW19: 6.45 | BX19: 7.17 | BY19: – | BZ19: – | CA19: 24 | CB19: 24 | CC19: 32 | CD19: – | CE19: – | CF19: – | CG19: – | CH19: – | CM19: A572 Gr. 55 | CN19: Grade 55 | CO19: 55 | CP19: 70 | CS19: =VLOOKUP(CT19,$G$3:$H$139,2,FALSE) -> L8X4X1 | CT19: 11.1 | CV19: =VLOOKUP(CW19,$G$140:$H$422,2,FALSE) -> WT7X250 | CW19: 73.5 | DB19: =VLOOKUP(DC19,$G$437:$H$464,2,FALSE) -> ST6X17.5 | DC19: 5.12 | DE19: =VLOOKUP(DF19,$G$465:$H$647,2,FALSE) -> 2L12X12X1 | DF19: 46 | DH19: W40X215 | DI19: 63.5 | DJ19: 39 | DK19: 0.65 | DL19: 52.6 | DM19: 6.45 | DN19: 964 | DO19: 859 | DQ19: W40X397 | DR19: 1800 | DS19: 32000 | DT19: W44X335 | DU19: 1620 | DV19: 335 | DW19: =VLOOKUP(DT19,$DQ$4:$DR$276,2,FALSE) -> 1620 | DX19: =VLOOKUP(DT19,$DQ$4:$DS$276,3,FALSE) -> 31100 | DZ19: W40X324 | EA19: 324 | EB19: 95.3 | EC19: 40.2 | ED19: 40 1/8 | EE19: 1 | EF19: 1 | EG19: 44928 | EH19: 15.9 | EI19: 15 7/8 | EJ19: 1.81 | EK19: 1 13/16 | EL19: 4.4 | EM19: 34.2 | EN19: 25600 | EO19: 1280 | EP19: 16.4 | EQ19: 1460 | ER19: 1220 | ES19: 153 | ET19: 3.58 | EU19: 239
B20: L | C20: L8X6X1 | D20: L8X6X1 | E20: F | F20: 44.2 | G20: 13.1 | H20: =D20 -> L8X6X1 | I20: 6 | J20: – | K20: – | L20: – | M20: – | N20: – | O20: – | P20: – | Q20: 8 | R20: – | S20: – | T20: – | U20: – | V20: – | W20: – | X20: 1 | Y20: – | Z20: – | AA20: 1.5 | AB20: 1.5 | AC20: – | AD20: 1.65 | AE20: 2.65 | AF20: – | AG20: 0.819 | AH20: 1.45 | AI20: – | AJ20: 8 | AK20: – | AL20: – | AM20: – | AN20: – | AO20: 80.9 | AP20: 27.3 | AQ20: 15.1 | AR20: 2.49 | AS20: 38.8 | AT20: 16.2 | AU20: 8.92 | AV20: 1.72 | AW20: 21.3 | AX20: 1.28 | AY20: 7.61 | AZ20: 4.34 | BA20: 16.3 | BB20: – | BC20: – | BD20: – | BE20: – | BF20: – | BG20: – | BH20: – | BI20: 3.88 | BJ20: – | BK20: 0.542 | BL20: 98.4 | BM20: 3.96 | BN20: 1.54 | BO20: 5.25 | BP20: 2.8 | BQ20: 2.71 | BR20: 1.54 | BS20: 24.8 | BT20: 63.9 | BU20: 18.7 | BV20: 7.61 | BW20: 7.86 | BX20: 13.8 | BY20: – | BZ20: – | CA20: 22 | CB20: 20 | CC20: 28 | CD20: – | CE20: – | CF20: – | CG20: – | CH20: – | CM20: A572 Gr. 60 | CN20: Grade 60 | CO20: 60 | CP20: 75 | CS20: =VLOOKUP(CT20,$G$3:$H$139,2,FALSE) -> L6X6X1 | CT20: 11 | CV20: =VLOOKUP(CW20,$G$140:$H$422,2,FALSE) -> WT18X243.5 | CW20: 71.7 | DB20: =VLOOKUP(DC20,$G$437:$H$464,2,FALSE) -> ST6X15.9 | DC20: 4.65 | DE20: =VLOOKUP(DF20,$G$465:$H$647,2,FALSE) -> 2L12X12X1 | DF20: 46 | DH20: W40X199 | DI20: 58.8 | DJ20: 38.7 | DK20: 0.65 | DL20: 52.6 | DM20: 7.39 | DN20: 869 | DO20: 770 | DQ20: W40X392 | DR20: 1710 | DS20: 29900 | DT20: W40X324 | DU20: 1460 | DV20: 324 | DW20: =VLOOKUP(DT20,$DQ$4:$DR$276,2,FALSE) -> 1460 | DX20: =VLOOKUP(DT20,$DQ$4:$DS$276,3,FALSE) -> 25600 | DZ20: W40X297 | EA20: 297 | EB20: 87.3 | EC20: 39.8 | ED20: 39 7/8 | EE20: 0.93 | EF20: 15/16 | EG20: 44928 | EH20: 15.8 | EI20: 15 7/8 | EJ20: 1.65 | EK20: 1 5/8 | EL20: 4.8 | EM20: 36.8 | EN20: 23200 | EO20: 1170 | EP20: 16.3 | EQ20: 1330 | ER20: 1090 | ES20: 138 | ET20: 3.54 | EU20: 215
B21: L | C21: L8X6X7/8 | D21: L8X6X7/8 | E21: F | F21: 39.1 | G21: 11.5 | H21: =D21 -> L8X6X7/8 | I21: 6 | J21: – | K21: – | L21: – | M21: – | N21: – | O21: – | P21: – | Q21: 8 | R21: – | S21: – | T21: – | U21: – | V21: – | W21: – | X21: 0.875 | Y21: – | Z21: – | AA21: 1.38 | AB21: 1.375 | AC21: – | AD21: 1.6 | AE21: 2.6 | AF21: – | AG21: 0.719 | AH21: 1.43 | AI21: – | AJ21: 9.14 | AK21: – | AL21: – | AM21: – | AN21: – | AO21: 72.4 | AP21: 24.3 | AQ21: 13.4 | AR21: 2.5 | AS21: 34.9 | AT21: 14.4 | AU21: 7.94 | AV21: 1.74 | AW21: 18.9 | AX21: 1.28 | AY21: 6.7 | AZ21: 2.96 | BA21: 11.3 | BB21: – | BC21: – | BD21: – | BE21: – | BF21: – | BG21: – | BH21: – | BI21: 3.92 | BJ21: – | BK21: 0.546 | BL21: 88.4 | BM21: 4.01 | BN21: 1.51 | BO21: 5.3 | BP21: 2.82 | BQ21: 2.65 | BR21: 1.57 | BS21: 22 | BT21: 58.5 | BU21: 16.7 | BV21: 6.7 | BW21: 7.13 | BX21: 12 | BY21: – | BZ21: – | CA21: 22 | CB21: 20 | CC21: 28 | CD21: – | CE21: – | CF21: – | CG21: – | CH21: – | CM21: A572 Gr. 65 | CN21: Grade 65 | CO21: 65 | CP21: 80 | CS21: =VLOOKUP(CT21,$G$3:$H$139,2,FALSE) -> L8X6X3/4 | CT21: 9.99 | CV21: =VLOOKUP(CW21,$G$140:$H$422,2,FALSE) -> WT7X227.5 | CW21: 66.9 | DB21: =VLOOKUP(DC21,$G$437:$H$464,2,FALSE) -> ST5X12.7 | DC21: 3.72 | DE21: =VLOOKUP(DF21,$G$465:$H$647,2,FALSE) -> 2L10X10X1-1/8 | DF21: 42.6 | DH21: W40X392 | DI21: 116 | DJ21: 41.6 | DK21: 1.42 | DL21: 24.1 | DM21: 2.45 | DN21: 1710 | DO21: 1440 | DQ21: W36X395 | DR21: 1710 | DS21: 28500 | DT21: W44X290 | DU21: 1410 | DV21: 290 | DW21: =VLOOKUP(DT21,$DQ$4:$DR$276,2,FALSE) -> 1410 | DX21: =VLOOKUP(DT21,$DQ$4:$DS$276,3,FALSE) -> 27000 | DZ21: W40X277 | EA21: 277 | EB21: 81.5 | EC21: 39.7 | ED21: 39 3/4 | EE21: 0.83 | EF21: 13/16 | EG21: 45123 | EH21: 15.8 | EI21: 15 7/8 | EJ21: 1.58 | EK21: 1 9/16 | EL21: 5.03 | EM21: 41.2 | EN21: 21900 | EO21: 1100 | EP21: 16.4 | EQ21: 1250 | ER21: 1040 | ES21: 132 | ET21: 3.58 | EU21: 204
B22: L | C22: L8X6X3/4 | D22: L8X6X3/4 | E22: F | F22: 33.8 | G22: 9.99 | H22: =D22 -> L8X6X3/4 | I22: 6 | J22: – | K22: – | L22: – | M22: – | N22: – | O22: – | P22: – | Q22: 8 | R22: – | S22: – | T22: – | U22: – | V22: – | W22: – | X22: 0.75 | Y22: – | Z22: – | AA22: 1.25 | AB22: 1.25 | AC22: – | AD22: 1.56 | AE22: 2.55 | AF22: – | AG22: 0.624 | AH22: 1.34 | AI22: – | AJ22: 10.7 | AK22: – | AL22: – | AM22: – | AN22: – | AO22: 63.5 | AP22: 21.1 | AQ22: 11.7 | AR22: 2.52 | AS22: 30.8 | AT22: 12.5 | AU22: 6.92 | AV22: 1.75 | AW22: 16.6 | AX22: 1.29 | AY22: 5.85 | AZ22: 1.9 | BA22: 7.28 | BB22: – | BC22: – | BD22: – | BE22: – | BF22: – | BG22: – | BH22: – | BI22: 3.95 | BJ22: – | BK22: 0.55 | BL22: 77.8 | BM22: 4.05 | BN22: 1.48 | BO22: 5.35 | BP22: 2.84 | BQ22: 2.6 | BR22: 1.59 | BS22: 19.2 | BT22: 52.6 | BU22: 14.5 | BV22: 5.85 | BW22: 6.38 | BX22: 10.4 | BY22: – | BZ22: – | CA22: 22 | CB22: 20 | CC22: 28 | CD22: – | CE22: – | CF22: – | CG22: – | CH22: – | CM22: A618 Gr. Ia, Ib, & II | CN22: Gr. Ia, Ib, & III | CO22: 50 | CP22: 70 | CS22: =VLOOKUP(CT22,$G$3:$H$139,2,FALSE) -> L8X4X7/8 | CT22: 9.79 | CV22: =VLOOKUP(CW22,$G$140:$H$422,2,FALSE) -> WT18X220.5 | CW22: 64.9 | DB22: =VLOOKUP(DC22,$G$437:$H$464,2,FALSE) -> ST4X11.5 | DC22: 3.38 | DE22: =VLOOKUP(DF22,$G$465:$H$647,2,FALSE) -> 2L10X10X1-1/8 | DF22: 42.6 | DH22: W40X331 | DI22: 97.7 | DJ22: 40.8 | DK22: 1.22 | DL22: 28 | DM22: 2.86 | DN22: 1430 | DO22: 1210 | DQ22: W40X372 | DR22: 1680 | DS22: 29600 | DT22: W44X262 | DU22: 1270 | DV22: 262 | DW22: =VLOOKUP(DT22,$DQ$4:$DR$276,2,FALSE) -> 1270 | DX22: =VLOOKUP(DT22,$DQ$4:$DS$276,3,FALSE) -> 24100 | DZ22: W40X249 | EA22: 249 | EB22: 73.5 | EC22: 39.4 | ED22: 39 3/8 | EE22: 0.75 | EF22: 44989 | EG22: 44993 | EH22: 15.8 | EI22: 15 3/4 | EJ22: 1.42 | EK22: 1 7/16 | EL22: 5.55 | EM22: 45.6 | EN22: 19600 | EO22: 993 | EP22: 16.3 | EQ22: 1120 | ER22: 926 | ES22: 118 | ET22: 3.55 | EU22: 182
B23: L | C23: L8X6X5/8 | D23: L8X6X5/8 | E23: F | F23: 28.5 | G23: 8.41 | H23: =D23 -> L8X6X5/8 | I23: 6 | J23: – | K23: – | L23: – | M23: – | N23: – | O23: – | P23: – | Q23: 8 | R23: – | S23: – | T23: – | U23: – | V23: – | W23: – | X23: 0.625 | Y23: – | Z23: – | AA23: 1.13 | AB23: 1.125 | AC23: – | AD23: 1.51 | AE23: 2.5 | AF23: – | AG23: 0.526 | AH23: 1.27 | AI23: – | AJ23: 12.8 | AK23: – | AL23: – | AM23: – | AN23: – | AO23: 54.2 | AP23: 17.9 | AQ23: 9.86 | AR23: 2.54 | AS23: 26.4 | AT23: 10.5 | AU23: 5.88 | AV23: 1.77 | AW23: 14.1 | AX23: 1.29 | AY23: 4.91 | AZ23: 1.12 | BA23: 4.33 | BB23: – | BC23: – | BD23: – | BE23: – | BF23: – | BG23: – | BH23: – | BI23: 3.98 | BJ23: – | BK23: 0.554 | BL23: 66.5 | BM23: 4.09 | BN23: 1.45 | BO23: 5.39 | BP23: 2.87 | BQ23: 2.53 | BR23: 1.62 | BS23: 16.3 | BT23: 45.9 | BU23: 12.3 | BV23: 4.91 | BW23: 5.57 | BX23: 8.7 | BY23: – | BZ23: – | CA23: 22 | CB23: 20 | CC23: 28 | CD23: – | CE23: – | CF23: – | CG23: – | CH23: – | CM23: A618 Gr. III | CN23: Gr. III | CO23: 50 | CP23: 65 | CS23: =VLOOKUP(CT23,$G$3:$H$139,2,FALSE) -> L6X6X7/8 | CT23: 9.75 | CV23: =VLOOKUP(CW23,$G$140:$H$422,2,FALSE) -> WT20X215.5 | CW23: 63.3 | DB23: =VLOOKUP(DC23,$G$437:$H$464,2,FALSE) -> ST4X9.2 | DC23: 2.7 | DE23: =VLOOKUP(DF23,$G$465:$H$647,2,FALSE) -> 2L10X10X1-1/8 | DF23: 42.6 | DH23: W40X327 | DI23: 95.9 | DJ23: 40.8 | DK23: 1.18 | DL23: 29 | DM23: 2.85 | DN23: 1410 | DO23: 1200 | DQ23: W14X730 | DR23: 1660 | DS23: 14300 | DT23: W40X249 | DU23: 1120 | DV23: 249 | DW23: =VLOOKUP(DT23,$DQ$4:$DR$276,2,FALSE) -> 1120 | DX23: =VLOOKUP(DT23,$DQ$4:$DS$276,3,FALSE) -> 19600 | DZ23: W40X215 | EA23: 215 | EB23: 63.5 | EC23: 39 | ED23: 39 | EE23: 0.65 | EF23: 45054 | EG23: 45062 | EH23: 15.8 | EI23: 15 3/4 | EJ23: 1.22 | EK23: 1 1/4 | EL23: 6.45 | EM23: 52.6 | EN23: 16700 | EO23: 859 | EP23: 16.2 | EQ23: 964 | ER23: 803 | ES23: 101 | ET23: 3.54 | EU23: 156
B24: L | C24: L8X6X9/16 | D24: L8X6X9/16 | E24: F | F24: 25.7 | G24: 7.61 | H24: =D24 -> L8X6X9/16 | I24: 6 | J24: – | K24: – | L24: – | M24: – | N24: – | O24: – | P24: – | Q24: 8 | R24: – | S24: – | T24: – | U24: – | V24: – | W24: – | X24: 0.563 | Y24: – | Z24: – | AA24: 1.06 | AB24: 1.0625 | AC24: – | AD24: 1.49 | AE24: 2.48 | AF24: – | AG24: 0.476 | AH24: 1.24 | AI24: – | AJ24: 14.2 | AK24: – | AL24: – | AM24: – | AN24: – | AO24: 49.4 | AP24: 16.2 | AQ24: 8.94 | AR24: 2.55 | AS24: 24.1 | AT24: 9.52 | AU24: 5.34 | AV24: 1.78 | AW24: 12.8 | AX24: 1.3 | AY24: 4.46 | AZ24: 0.823 | BA24: 3.2 | BB24: – | BC24: – | BD24: – | BE24: – | BF24: – | BG24: – | BH24: – | BI24: 3.99 | BJ24: – | BK24: 0.556 | BL24: 60.7 | BM24: 4.11 | BN24: 1.44 | BO24: 5.41 | BP24: 2.87 | BQ24: 2.51 | BR24: 1.62 | BS24: 14.8 | BT24: 42.2 | BU24: 11.2 | BV24: 4.46 | BW24: 5.1 | BX24: 7.9 | BY24: – | BZ24: – | CA24: 22 | CB24: 20 | CC24: 28 | CD24: – | CE24: – | CF24: – | CG24: – | CH24: – | CM24: A709 Gr. 50 | CN24: 50 | CO24: 50 | CP24: 65 | CS24: =VLOOKUP(CT24,$G$3:$H$139,2,FALSE) -> L8X8X5/8 | CT24: 9.69 | CV24: =VLOOKUP(CW24,$G$140:$H$422,2,FALSE) -> WT7X213 | CW24: 62.7 | DB24: =VLOOKUP(DC24,$G$437:$H$464,2,FALSE) -> ST3X8.6 | DC24: 2.53 | DE24: =VLOOKUP(DF24,$G$465:$H$647,2,FALSE) -> 2L10X10X1 | DF24: 38 | DH24: W40X294 | DI24: 86.2 | DJ24: 40.4 | DK24: 1.06 | DL24: 32.2 | DM24: 3.11 | DN24: 1270 | DO24: 1080 | DQ24: W40X362 | DR24: 1640 | DS24: 28900 | DT24: W44X230 | DU24: 1100 | DV24: 230 | DW24: =VLOOKUP(DT24,$DQ$4:$DR$276,2,FALSE) -> 1100 | DX24: =VLOOKUP(DT24,$DQ$4:$DS$276,3,FALSE) -> 20800 | DZ24: W40X199 | EA24: 199 | EB24: 58.8 | EC24: 38.7 | ED24: 38 5/8 | EE24: 0.65 | EF24: 45054 | EG24: 45062 | EH24: 15.8 | EI24: 15 3/4 | EJ24: 1.07 | EK24: 1 1/16 | EL24: 7.39 | EM24: 52.6 | EN24: 14900 | EO24: 770 | EP24: 16 | EQ24: 869 | ER24: 695 | ES24: 88.2 | ET24: 3.45 | EU24: 137
B25: L | C25: L8X6X1/2 | D25: L8X6X1/2 | E25: F | F25: 23 | G25: 6.8 | H25: =D25 -> L8X6X1/2 | I25: 6 | J25: – | K25: – | L25: – | M25: – | N25: – | O25: – | P25: – | Q25: 8 | R25: – | S25: – | T25: – | U25: – | V25: – | W25: – | X25: 0.5 | Y25: – | Z25: – | AA25: 1 | AB25: 1 | AC25: – | AD25: 1.46 | AE25: 2.46 | AF25: – | AG25: 0.425 | AH25: 1.2 | AI25: – | AJ25: 16 | AK25: – | AL25: – | AM25: – | AN25: – | AO25: 44.4 | AP25: 14.6 | AQ25: 8.01 | AR25: 2.55 | AS25: 21.7 | AT25: 8.52 | AU25: 4.79 | AV25: 1.79 | AW25: 11.5 | AX25: 1.3 | AY25: 3.98 | AZ25: 0.584 | BA25: 2.28 | BB25: – | BC25: – | BD25: – | BE25: – | BF25: – | BG25: – | BH25: – | BI25: 4.01 | BJ25: – | BK25: 0.557 | BL25: 54.6 | BM25: 4.14 | BN25: 1.44 | BO25: 5.43 | BP25: 2.89 | BQ25: 2.47 | BR25: 1.64 | BS25: 13.2 | BT25: 37.9 | BU25: 10.1 | BV25: 3.98 | BW25: 4.66 | BX25: 7.01 | BY25: – | BZ25: – | CA25: 22 | CB25: 20 | CC25: 28 | CD25: – | CE25: – | CF25: – | CG25: – | CH25: – | CM25: A709 Gr. 50S | CN25: 50S | CO25: 50 | CP25: 65 | CS25: =VLOOKUP(CT25,$G$3:$H$139,2,FALSE) -> L8X8X9/16 | CT25: 8.77 | CV25: =VLOOKUP(CW25,$G$140:$H$422,2,FALSE) -> WT7X199 | CW25: 58.4 | DB25: =VLOOKUP(DC25,$G$437:$H$464,2,FALSE) -> ST3X6.25 | DC25: 1.83 | DE25: =VLOOKUP(DF25,$G$465:$H$647,2,FALSE) -> 2L10X10X1 | DF25: 38 | DH25: W40X278 | DI25: 82.3 | DJ25: 40.2 | DK25: 1.03 | DL25: 33.3 | DM25: 3.31 | DN25: 1190 | DO25: 1020 | DQ25: W44X335 | DR25: 1620 | DS25: 31100 | DT25: W40X215 | DU25: 964 | DV25: 215 | DW25: =VLOOKUP(DT25,$DQ$4:$DR$276,2,FALSE) -> 964 | DX25: =VLOOKUP(DT25,$DQ$4:$DS$276,3,FALSE) -> 16700 | DZ25: W40X392 | EA25: 392 | EB25: 116 | EC25: 41.6 | ED25: 41 5/8 | EE25: 1.42 | EF25: 1 7/16 | EG25: 44989 | EH25: 12.4 | EI25: 12 3/8 | EJ25: 2.52 | EK25: 2 1/2 | EL25: 2.45 | EM25: 24.1 | EN25: 29900 | EO25: 1440 | EP25: 16.1 | EQ25: 1710 | ER25: 803 | ES25: 130 | ET25: 2.64 | EU25: 212
B26: L | C26: L8X6X7/16 | D26: L8X6X7/16 | E26: F | F26: 20.2 | G26: 5.99 | H26: =D26 -> L8X6X7/16 | I26: 6 | J26: – | K26: – | L26: – | M26: – | N26: – | O26: – | P26: – | Q26: 8 | R26: – | S26: – | T26: – | U26: – | V26: – | W26: – | X26: 0.438 | Y26: – | Z26: – | AA26: 0.938 | AB26: 0.9375 | AC26: – | AD26: 1.44 | AE26: 2.43 | AF26: – | AG26: 0.374 | AH26: 1.15 | AI26: – | AJ26: 18.3 | AK26: – | AL26: – | AM26: – | AN26: – | AO26: 39.3 | AP26: 12.9 | AQ26: 7.06 | AR26: 2.56 | AS26: 19.3 | AT26: 7.5 | AU26: 4.23 | AV26: 1.8 | AW26: 10.2 | AX26: 1.31 | AY26: 3.52 | AZ26: 0.396 | BA26: 1.55 | BB26: – | BC26: – | BD26: – | BE26: – | BF26: – | BG26: – | BH26: – | BI26: 4.02 | BJ26: – | BK26: 0.559 | BL26: 48.4 | BM26: 4.16 | BN26: 1.42 | BO26: 5.46 | BP26: 2.9 | BQ26: 2.44 | BR26: 1.65 | BS26: 11.6 | BT26: 34.1 | BU26: 8.86 | BV26: 3.52 | BW26: 4.18 | BX26: 6.18 | BY26: – | BZ26: – | CA26: 22 | CB26: 20 | CC26: 28 | CD26: – | CE26: – | CF26: – | CG26: – | CH26: – | CM26: A709 Gr. 50W | CN26: 50W | CO26: 50 | CP26: 70 | CS26: =VLOOKUP(CT26,$G$3:$H$139,2,FALSE) -> L8X4X3/4 | CT26: 8.49 | CV26: =VLOOKUP(CW26,$G$140:$H$422,2,FALSE) -> WT20X198.5 | CW26: 58.3 | DB26: =VLOOKUP(DC26,$G$437:$H$464,2,FALSE) -> ST2.5X5 | DC26: 1.46 | DE26: =VLOOKUP(DF26,$G$465:$H$647,2,FALSE) -> 2L10X10X1 | DF26: 38 | DH26: W40X264 | DI26: 77.4 | DJ26: 40 | DK26: 0.96 | DL26: 35.6 | DM26: 3.45 | DN26: 1130 | DO26: 971 | DQ26: W33X387 | DR26: 1560 | DS26: 24300 | DT26: W40X211 | DU26: 906 | DV26: 211 | DW26: =VLOOKUP(DT26,$DQ$4:$DR$276,2,FALSE) -> 906 | DX26: =VLOOKUP(DT26,$DQ$4:$DS$276,3,FALSE) -> 15500 | DZ26: W40X331 | EA26: 331 | EB26: 97.7 | EC26: 40.8 | ED26: 40 3/4 | EE26: 1.22 | EF26: 1 1/4 | EG26: 45054 | EH26: 12.2 | EI26: 12 1/8 | EJ26: 2.13 | EK26: 2 1/8 | EL26: 2.86 | EM26: 28 | EN26: 24700 | EO26: 1210 | EP26: 15.9 | EQ26: 1430 | ER26: 644 | ES26: 106 | ET26: 2.57 | EU26: 172
B27: L | C27: L8X4X1 | D27: L8X4X1 | E27: F | F27: 37.4 | G27: 11.1 | H27: =D27 -> L8X4X1 | I27: 4 | J27: – | K27: – | L27: – | M27: – | N27: – | O27: – | P27: – | Q27: 8 | R27: – | S27: – | T27: – | U27: – | V27: – | W27: – | X27: 1 | Y27: – | Z27: – | AA27: 1.5 | AB27: 1.5 | AC27: – | AD27: 1.04 | AE27: 3.03 | AF27: – | AG27: 0.694 | AH27: 2.45 | AI27: – | AJ27: 8 | AK27: – | AL27: – | AM27: – | AN27: – | AO27: 69.7 | AP27: 24.3 | AQ27: 14 | AR27: 2.51 | AS27: 11.6 | AT27: 7.73 | AU27: 3.94 | AV27: 1.03 | AW27: 7.83 | AX27: 0.844 | AY27: 3.45 | AZ27: 3.68 | BA27: 12.9 | BB27: – | BC27: – | BD27: – | BE27: – | BF27: – | BG27: – | BH27: – | BI27: 3.75 | BJ27: – | BK27: 0.247 | BL27: 73.4 | BM27: 3.17 | BN27: 2.69 | BO27: 4.95 | BP27: 2.27 | BQ27: 1.74 | BR27: 0.667 | BS27: 23.2 | BT27: 27.3 | BU27: 14.8 | BV27: 3.45 | BW27: 4.5 | BX27: 11.7 | BY27: – | BZ27: – | CA27: 20 | CB27: 16 | CC27: 24 | CD27: – | CE27: – | CF27: – | CG27: – | CH27: – | CM27: A913 Gr. 50 | CN27: 50 | CO27: 50 | CP27: 65 | CS27: =VLOOKUP(CT27,$G$3:$H$139,2,FALSE) -> L6X6X3/4 | CT27: 8.46 | CV27: =VLOOKUP(CW27,$G$140:$H$422,2,FALSE) -> WT18X197.5 | CW27: 58.1 | DB27: =VLOOKUP(DC27,$G$437:$H$464,2,FALSE) -> ST2X4.75 | DC27: 1.4 | DE27: =VLOOKUP(DF27,$G$465:$H$647,2,FALSE) -> 2L10X10X7/8 | DF27: 33.6 | DH27: W40X235 | DI27: 69.1 | DJ27: 39.7 | DK27: 0.83 | DL27: 41.2 | DM27: 3.77 | DN27: 1010 | DO27: 875 | DQ27: W36X361 | DR27: 1550 | DS27: 25700 | DT27: W40X199 | DU27: 869 | DV27: 199 | DW27: =VLOOKUP(DT27,$DQ$4:$DR$276,2,FALSE) -> 869 | DX27: =VLOOKUP(DT27,$DQ$4:$DS$276,3,FALSE) -> 14900 | DZ27: W40X327 | EA27: 327 | EB27: 95.9 | EC27: 40.8 | ED27: 40 3/4 | EE27: 1.18 | EF27: 1 3/16 | EG27: 45054 | EH27: 12.1 | EI27: 12 1/8 | EJ27: 2.13 | EK27: 2 1/8 | EL27: 2.85 | EM27: 29 | EN27: 24500 | EO27: 1200 | EP27: 16 | EQ27: 1410 | ER27: 640 | ES27: 105 | ET27: 2.58 | EU27: 170
B28: L | C28: L8X4X7/8 | D28: L8X4X7/8 | E28: F | F28: 33.1 | G28: 9.79 | H28: =D28 -> L8X4X7/8 | I28: 4 | J28: – | K28: – | L28: – | M28: – | N28: – | O28: – | P28: – | Q28: 8 | R28: – | S28: – | T28: – | U28: – | V28: – | W28: – | X28: 0.875 | Y28: – | Z28: – | AA28: 1.38 | AB28: 1.375 | AC28: – | AD28: 0.997 | AE28: 2.99 | AF28: – | AG28: 0.612 | AH28: 2.41 | AI28: – | AJ28: 9.14 | AK28: – | AL28: – | AM28: – | AN28: – | AO28: 62.6 | AP28: 21.7 | AQ28: 12.5 | AR28: 2.53 | AS28: 10.5 | AT28: 6.77 | AU28: 3.51 | AV28: 1.04 | AW28: 6.97 | AX28: 0.846 | AY28: 3.04 | AZ28: 2.51 | BA28: 8.89 | BB28: – | BC28: – | BD28: – | BE28: – | BF28: – | BG28: – | BH28: – | BI28: 3.78 | BJ28: – | BK28: 0.252 | BL28: 66.1 | BM28: 3.21 | BN28: 2.66 | BO28: 4.99 | BP28: 2.29 | BQ28: 1.7 | BR28: 0.681 | BS28: 20.6 | BT28: 24.8 | BU28: 13.2 | BV28: 3.04 | BW28: 4.1 | BX28: 10.2 | BY28: – | BZ28: – | CA28: 20 | CB28: 16 | CC28: 24 | CD28: – | CE28: – | CF28: – | CG28: – | CH28: – | CM28: A913 Gr. 60 | CN28: 60 | CO28: 60 | CP28: 75 | CS28: =VLOOKUP(CT28,$G$3:$H$139,2,FALSE) -> L8X6X5/8 | CT28: 8.41 | CV28: =VLOOKUP(CW28,$G$140:$H$422,2,FALSE) -> WT20X196 | CW28: 57.8 | DB28: =VLOOKUP(DC28,$G$437:$H$464,2,FALSE) -> ST2X3.85 | DC28: 1.13 | DE28: =VLOOKUP(DF28,$G$465:$H$647,2,FALSE) -> 2L10X10X7/8 | DF28: 33.6 | DH28: W40X211 | DI28: 62.1 | DJ28: 39.4 | DK28: 0.75 | DL28: 45.6 | DM28: 4.17 | DN28: 906 | DO28: 786 | DQ28: W14X665 | DR28: 1480 | DS28: 12400 | DT28: W40X183 | DU28: 774 | DV28: 183 | DW28: =VLOOKUP(DT28,$DQ$4:$DR$276,2,FALSE) -> 774 | DX28: =VLOOKUP(DT28,$DQ$4:$DS$276,3,FALSE) -> 13200 | DZ28: W40X294 | EA28: 294 | EB28: 86.2 | EC28: 40.4 | ED28: 40 3/8 | EE28: 1.06 | EF28: 1 1/16 | EG28: 45185 | EH28: 12 | EI28: 12 | EJ28: 1.93 | EK28: 1 15/16 | EL28: 3.11 | EM28: 32.2 | EN28: 21900 | EO28: 1080 | EP28: 15.9 | EQ28: 1270 | ER28: 562 | ES28: 93.5 | ET28: 2.55 | EU28: 150
B29: L | C29: L8X4X3/4 | D29: L8X4X3/4 | E29: F | F29: 28.7 | G29: 8.49 | H29: =D29 -> L8X4X3/4 | I29: 4 | J29: – | K29: – | L29: – | M29: – | N29: – | O29: – | P29: – | Q29: 8 | R29: – | S29: – | T29: – | U29: – | V29: – | W29: – | X29: 0.75 | Y29: – | Z29: – | AA29: 1.25 | AB29: 1.25 | AC29: – | AD29: 0.949 | AE29: 2.94 | AF29: – | AG29: 0.531 | AH29: 2.34 | AI29: – | AJ29: 10.7 | AK29: – | AL29: – | AM29: – | AN29: – | AO29: 55 | AP29: 18.9 | AQ29: 10.9 | AR29: 2.55 | AS29: 9.37 | AT29: 5.82 | AU29: 3.07 | AV29: 1.05 | AW29: 6.14 | AX29: 0.85 | AY29: 2.65 | AZ29: 1.61 | BA29: 5.75 | BB29: – | BC29: – | BD29: – | BE29: – | BF29: – | BG29: – | BH29: – | BI29: 3.8 | BJ29: – | BK29: 0.257 | BL29: 58.2 | BM29: 3.24 | BN29: 2.61 | BO29: 5.04 | BP29: 2.32 | BQ29: 1.65 | BR29: 0.704 | BS29: 18 | BT29: 22.3 | BU29: 11.5 | BV29: 2.65 | BW29: 3.72 | BX29: 8.72 | BY29: – | BZ29: – | CA29: 20 | CB29: 16 | CC29: 24 | CD29: – | CE29: – | CF29: – | CG29: – | CH29: – | CM29: A913 Gr. 65 | CN29: 65 | CO29: 65 | CP29: 80 | CS29: =VLOOKUP(CT29,$G$3:$H$139,2,FALSE) -> L6X4X7/8 | CT29: 8 | CV29: =VLOOKUP(CW29,$G$140:$H$422,2,FALSE) -> WT15X195.5 | CW29: 57.6 | DB29: =VLOOKUP(DC29,$G$437:$H$464,2,FALSE) -> ST1.5X3.75 | DC29: 1.1 | DE29: =VLOOKUP(DF29,$G$465:$H$647,2,FALSE) -> 2L10X10X7/8 | DF29: 33.6 | DH29: W40X183 | DI29: 53.3 | DJ29: 39 | DK29: 0.65 | DL29: 52.6 | DM29: 4.92 | DN29: 774 | DO29: 675 | DQ29: W40X324 | DR29: 1460 | DS29: 25600 | DT29: W36X182 | DU29: 718 | DV29: 182 | DW29: 718 | DX29: 11300 | DZ29: W40X278 | EA29: 278 | EB29: 82.3 | EC29: 40.2 | ED29: 40 1/8 | EE29: 1.03 | EF29: 1 | EG29: 44928 | EH29: 12 | EI29: 12 | EJ29: 1.81 | EK29: 1 13/16 | EL29: 3.31 | EM29: 33.3 | EN29: 20500 | EO29: 1020 | EP29: 15.8 | EQ29: 1190 | ER29: 521 | ES29: 87.1 | ET29: 2.52 | EU29: 140
B30: L | C30: L8X4X5/8 | D30: L8X4X5/8 | E30: F | F30: 24.2 | G30: 7.16 | H30: =D30 -> L8X4X5/8 | I30: 4 | J30: – | K30: – | L30: – | M30: – | N30: – | O30: – | P30: – | Q30: 8 | R30: – | S30: – | T30: – | U30: – | V30: – | W30: – | X30: 0.625 | Y30: – | Z30: – | AA30: 1.13 | AB30: 1.125 | AC30: – | AD30: 0.902 | AE30: 2.89 | AF30: – | AG30: 0.448 | AH30: 2.27 | AI30: – | AJ30: 12.8 | AK30: – | AL30: – | AM30: – | AN30: – | AO30: 47 | AP30: 16.1 | AQ30: 9.2 | AR30: 2.56 | AS30: 8.11 | AT30: 4.86 | AU30: 2.62 | AV30: 1.06 | AW30: 5.24 | AX30: 0.856 | AY30: 2.24 | AZ30: 0.955 | BA30: 3.42 | BB30: – | BC30: – | BD30: – | BE30: – | BF30: – | BG30: – | BH30: – | BI30: 3.83 | BJ30: – | BK30: 0.262 | BL30: 49.9 | BM30: 3.28 | BN30: 2.57 | BO30: 5.09 | BP30: 2.34 | BQ30: 1.61 | BR30: 0.725 | BS30: 15.2 | BT30: 19.4 | BU30: 9.8 | BV30: 2.24 | BW30: 3.25 | BX30: 7.23 | BY30: – | BZ30: – | CA30: 20 | CB30: 16 | CC30: 24 | CD30: – | CE30: – | CF30: – | CG30: – | CH30: – | CM30: A913 Gr. 70 | CN30: 70 | CO30: 70 | CP30: 90 | CS30: =VLOOKUP(CT30,$G$3:$H$139,2,FALSE) -> L6X4X7/8 | CT30: 8 | CV30: =VLOOKUP(CW30,$G$140:$H$422,2,FALSE) -> WT16.5X193.5 | CW30: 57 | DB30: =VLOOKUP(DC30,$G$437:$H$464,2,FALSE) -> ST1.5X2.85 | DC30: 0.83 | DE30: =VLOOKUP(DF30,$G$465:$H$647,2,FALSE) -> 2L10X10X7/8 | DF30: 33.6 | DH30: W40X167 | DI30: 49.3 | DJ30: 38.6 | DK30: 0.65 | DL30: 52.6 | DM30: 5.76 | DN30: 693 | DO30: 600 | DQ30: W30X391 | DR30: 1450 | DS30: 20700 | DT30: W40X167 | DU30: 693 | DV30: 167 | DW30: =VLOOKUP(DT30,$DQ$4:$DR$276,2,FALSE) -> 693 | DX30: =VLOOKUP(DT30,$DQ$4:$DS$276,3,FALSE) -> 11600 | DZ30: W40X264 | EA30: 264 | EB30: 77.4 | EC30: 40 | ED30: 40 | EE30: 0.96 | EF30: 15/16 | EG30: 44928 | EH30: 11.9 | EI30: 11 7/8 | EJ30: 1.73 | EK30: 1 3/4 | EL30: 3.45 | EM30: 35.6 | EN30: 19400 | EO30: 971 | EP30: 15.8 | EQ30: 1130 | ER30: 493 | ES30: 82.6 | ET30: 2.52 | EU30: 132
B31: L | C31: L8X4X9/16 | D31: L8X4X9/16 | E31: F | F31: 21.9 | G31: 6.49 | H31: =D31 -> L8X4X9/16 | I31: 4 | J31: – | K31: – | L31: – | M31: – | N31: – | O31: – | P31: – | Q31: 8 | R31: – | S31: – | T31: – | U31: – | V31: – | W31: – | X31: 0.563 | Y31: – | Z31: – | AA31: 1.06 | AB31: 1.0625 | AC31: – | AD31: 0.878 | AE31: 2.86 | AF31: – | AG31: 0.406 | AH31: 2.23 | AI31: – | AJ31: 14.2 | AK31: – | AL31: – | AM31: – | AN31: – | AO31: 42.9 | AP31: 14.6 | AQ31: 8.34 | AR31: 2.57 | AS31: 7.44 | AT31: 4.39 | AU31: 2.38 | AV31: 1.07 | AW31: 4.78 | AX31: 0.859 | AY31: 2.03 | AZ31: 0.704 | BA31: 2.53 | BB31: – | BC31: – | BD31: – | BE31: – | BF31: – | BG31: – | BH31: – | BI31: 3.84 | BJ31: – | BK31: 0.264 | BL31: 45.6 | BM31: 3.29 | BN31: 2.54 | BO31: 5.12 | BP31: 2.36 | BQ31: 1.58 | BR31: 0.736 | BS31: 13.9 | BT31: 18 | BU31: 8.91 | BV31: 2.03 | BW31: 3.03 | BX31: 6.49 | BY31: – | BZ31: – | CA31: 20 | CB31: 16 | CC31: 24 | CD31: – | CE31: – | CF31: – | CG31: – | CH31: – | CM31: A992 | CO31: 50 | CP31: 65 | CS31: =VLOOKUP(CT31,$G$3:$H$139,2,FALSE) -> L8X8X1/2 | CT31: 7.84 | CV31: =VLOOKUP(CW31,$G$140:$H$422,2,FALSE) -> WT20X186 | CW31: 54.7 | DE31: =VLOOKUP(DF31,$G$465:$H$647,2,FALSE) -> 2L10X10X7/8 | DF31: 33.6 | DH31: W40X149 | DI31: 43.8 | DJ31: 38.2 | DK31: 0.63 | DL31: 54.3 | DM31: 7.11 | DN31: 598 | DO31: 513 | DQ31: W40X331 | DR31: 1430 | DS31: 24700 | DT31: W36X160 | DU31: 624 | DV31: 160 | DW31: =VLOOKUP(DT31,$DQ$4:$DR$276,2,FALSE) -> 624 | DX31: =VLOOKUP(DT31,$DQ$4:$DS$276,3,FALSE) -> 9760 | DZ31: W40X235 | EA31: 235 | EB31: 69.1 | EC31: 39.7 | ED31: 39 3/4 | EE31: 0.83 | EF31: 13/16 | EG31: 45123 | EH31: 11.9 | EI31: 11 7/8 | EJ31: 1.58 | EK31: 1 9/16 | EL31: 3.77 | EM31: 41.2 | EN31: 17400 | EO31: 875 | EP31: 15.9 | EQ31: 1010 | ER31: 444 | ES31: 74.6 | ET31: 2.54 | EU31: 118
B32: L | C32: L8X4X1/2 | D32: L8X4X1/2 | E32: F | F32: 19.6 | G32: 5.8 | H32: =D32 -> L8X4X1/2 | I32: 4 | J32: – | K32: – | L32: – | M32: – | N32: – | O32: – | P32: – | Q32: 8 | R32: – | S32: – | T32: – | U32: – | V32: – | W32: – | X32: 0.5 | Y32: – | Z32: – | AA32: 1 | AB32: 1 | AC32: – | AD32: 0.854 | AE32: 2.84 | AF32: – | AG32: 0.363 | AH32: 2.2 | AI32: – | AJ32: 16 | AK32: – | AL32: – | AM32: – | AN32: – | AO32: 38.6 | AP32: 13.1 | AQ32: 7.48 | AR32: 2.58 | AS32: 6.75 | AT32: 3.91 | AU32: 2.15 | AV32: 1.08 | AW32: 4.32 | AX32: 0.863 | AY32: 1.82 | AZ32: 0.501 | BA32: 1.8 | BB32: – | BC32: – | BD32: – | BE32: – | BF32: – | BG32: – | BH32: – | BI32: 3.86 | BJ32: – | BK32: 0.266 | BL32: 41 | BM32: 3.31 | BN32: 2.52 | BO32: 5.14 | BP32: 2.37 | BQ32: 1.56 | BR32: 0.744 | BS32: 12.4 | BT32: 16.3 | BU32: 7.98 | BV32: 1.82 | BW32: 2.77 | BX32: 5.81 | BY32: – | BZ32: – | CA32: 20 | CB32: 16 | CC32: 24 | CD32: – | CE32: – | CF32: – | CG32: – | CH32: – | CM32: A1065 Gr. 50 | CN32: Gr. 50 | CO32: 50 | CP32: 60 | CS32: =VLOOKUP(CT32,$G$3:$H$139,2,FALSE) -> L7X4X3/4 | CT32: 7.74 | CV32: =VLOOKUP(CW32,$G$140:$H$422,2,FALSE) -> WT12X185 | CW32: 54.5 | DE32: =VLOOKUP(DF32,$G$465:$H$647,2,FALSE) -> 2L10X10X7/8 | DF32: 33.6 | DH32: W36X925 | DI32: 272 | DJ32: 43.1 | DK32: 3.02 | DL32: 10.8 | DM32: 2.05 | DN32: 4130 | DO32: 3390 | DQ32: W33X354 | DR32: 1420 | DS32: 22000 | DT32: W40X149 | DU32: 598 | DV32: 149 | DW32: =VLOOKUP(DT32,$DQ$4:$DR$276,2,FALSE) -> 598 | DX32: =VLOOKUP(DT32,$DQ$4:$DS$276,3,FALSE) -> 9800 | DZ32: W40X211 | EA32: 211 | EB32: 62.1 | EC32: 39.4 | ED32: 39 3/8 | EE32: 0.75 | EF32: 44989 | EG32: 44993 | EH32: 11.8 | EI32: 11 3/4 | EJ32: 1.42 | EK32: 1 7/16 | EL32: 4.17 | EM32: 45.6 | EN32: 15500 | EO32: 786 | EP32: 15.8 | EQ32: 906 | ER32: 390 | ES32: 66.1 | ET32: 2.51 | EU32: 105
B33: L | C33: L8X4X7/16 | D33: L8X4X7/16 | E33: F | F33: 17.2 | G33: 5.11 | H33: =D33 -> L8X4X7/16 | I33: 4 | J33: – | K33: – | L33: – | M33: – | N33: – | O33: – | P33: – | Q33: 8 | R33: – | S33: – | T33: – | U33: – | V33: – | W33: – | X33: 0.438 | Y33: – | Z33: – | AA33: 0.938 | AB33: 0.9375 | AC33: – | AD33: 0.829 | AE33: 2.81 | AF33: – | AG33: 0.319 | AH33: 2.16 | AI33: – | AJ33: 18.3 | AK33: – | AL33: – | AM33: – | AN33: – | AO33: 34.2 | AP33: 11.6 | AQ33: 6.59 | AR33: 2.59 | AS33: 6.03 | AT33: 3.42 | AU33: 1.9 | AV33: 1.09 | AW33: 3.84 | AX33: 0.867 | AY33: 1.61 | AZ33: 0.34 | BA33: 1.22 | BB33: – | BC33: – | BD33: – | BE33: – | BF33: – | BG33: – | BH33: – | BI33: 3.87 | BJ33: – | BK33: 0.268 | BL33: 36.4 | BM33: 3.33 | BN33: 2.5 | BO33: 5.17 | BP33: 2.39 | BQ33: 1.53 | BR33: 0.758 | BS33: 10.9 | BT33: 14.6 | BU33: 7.04 | BV33: 1.61 | BW33: 2.51 | BX33: 5.07 | BY33: – | BZ33: – | CA33: 20 | CB33: 16 | CC33: 24 | CD33: – | CE33: – | CF33: – | CG33: – | CH33: – | CM33: A588 | CO33: 50 | CP33: 70 | CS33: =VLOOKUP(CT33,$G$3:$H$139,2,FALSE) -> L8X6X9/16 | CT33: 7.61 | CV33: =VLOOKUP(CW33,$G$140:$H$422,2,FALSE) -> WT7X185 | CW33: 54.4 | DE33: =VLOOKUP(DF33,$G$465:$H$647,2,FALSE) -> 2L8X8X1 | DF33: 30.2 | DH33: W36X853 | DI33: 251 | DJ33: 43.1 | DK33: 2.52 | DL33: 12.9 | DM33: 2.01 | DN33: 3920 | DO33: 3250 | DQ33: W44X290 | DR33: 1410 | DS33: 27000 | DT33: W33X141 | DU33: 514 | DV33: 141 | DW33: =VLOOKUP(DT33,$DQ$4:$DR$276,2,FALSE) -> 514 | DX33: =VLOOKUP(DT33,$DQ$4:$DS$276,3,FALSE) -> 7450 | DZ33: W40X183 | EA33: 183 | EB33: 53.3 | EC33: 39 | ED33: 39 | EE33: 0.65 | EF33: 45054 | EG33: 45062 | EH33: 11.8 | EI33: 11 3/4 | EJ33: 1.2 | EK33: 1 3/16 | EL33: 4.92 | EM33: 52.6 | EN33: 13200 | EO33: 675 | EP33: 15.7 | EQ33: 774 | ER33: 331 | ES33: 56 | ET33: 2.49 | EU33: 88.3
